Workbook

Sheet Instructions

Sheet Report Card
D5: OYO STATE MINISTRY OF EDUCATION, SCIENCE AND TECHNOLOGY | L5: Insert School Logo
D6: COMPREHENSIVE HIGH SCHOOL, IGBOPE
D7: STUDENT REPORT CARD
B8: 19 | C8: Student Name: | D8: =VLOOKUP(B8,Db!A4:B503,2,0) | G8: Gender | H8: =VLOOKUP(B8,Db!A4:E503,4,0) | I8: Adm. No. | J8: =VLOOKUP(B8,Db!A4:C503,3,0) | K8: Class: | L8: =VLOOKUP(B8,Db!A4:E503,5,0)
B9: Number of Subjects Offered: | D9: =COUNTIF(D14:D30,"=100") | E9: Number Passed: | F9: =COUNTIF(J14:J30,">=40") | G9: Number Failed: | H9: =D9-F9 | I9: Number of Students in Class: | J9: =VLOOKUP(B8,Db!A4:F503,6,0) | K9: Class Position | L9: =VLOOKUP(B8,Db!A4:DI503,113,0)
B10: No of Times School Opened: | D10: =VLOOKUP(B8,Db!A4:G503,7,0) | E10: No of Times Present: | F10: =VLOOKUP(B8,Db!A4:H503,8,0) | G10: No of Times Absent: | H10: =VLOOKUP(B8,Db!A4:I503,9,0) | I10: Academic Session: | J10: =VLOOKUP(B8,Db!A4:DR503,122,0) | K10: Term: | L10: =VLOOKUP(B8,Db!A4:DS503,123,0)
B11: COGNITIVE (ACADEMIC PERFORMANCE)
B12: S/NO | C12: Subject | D12: Marks Obtainable | E12: 3rd Term C.A. | F12: 3rd Term Exam | G12: Total Mark | K12: Grade Obtained | L12: Remarks
E13: 0.3 | F13: 0.7 | G13: 3rd Term Total (100%) | H13: 2nd Term Total (100%) | I13: 1st Term Total (100%) | J13: Average Score in %
B14: 1 | C14: =Db!J2 | D14: =IF(AND(G14=0,H14=0,I14=0),"--",100) | E14: =VLOOKUP(B8,Db!A4:J503,10,0) | F14: =VLOOKUP(B8,Db!A4:K503,11,0) | G14: =VLOOKUP(B8,Db!A4:L503,12,0) | H14: =VLOOKUP(B8,Db!A4:M503,13,0) | I14: =VLOOKUP(B8,Db!A4:N503,14,0) | J14: =VLOOKUP(B8,Db!A4:O503,15,0) | K14: =IF(J14>=70,"A",IF(J14>=50,"C",IF(J14>=40,"P",IF(J14>=1,"F","NA")))) | L14: =IF(K14="A","DISTINCTION",IF(K14="C","GOOD",IF(K14="P","PASS",IF(K14="F","FAIL",IF(K14="NA","NOT APPLICABLE","")))))
B15: 2 | C15: =Db!P2 | D15: =IF(AND(G15=0,H15=0,I15=0),"--",100) | E15: =VLOOKUP(B8,Db!A4:P503,16,0) | F15: =VLOOKUP(B8,Db!A4:Q503,17,0) | G15: =VLOOKUP(B8,Db!A4:R503,18,0) | H15: =VLOOKUP(B8,Db!A4:S503,19,0) | I15: =VLOOKUP(B8,Db!A4:T503,20,0) | J15: =VLOOKUP(B8,Db!A4:U503,21,0) | K15: =IF(J15>=70,"A",IF(J15>=50,"C",IF(J15>=40,"P",IF(J15>=1,"F","NA")))) | L15: =IF(K15="A","DISTINCTION",IF(K15="C","GOOD",IF(K15="P","PASS",IF(K15="F","FAIL",IF(K15="NA","NOT APPLICABLE","")))))
B16: 3 | C16: =Db!V2 | D16: =IF(AND(G16=0,H16=0,I16=0),"--",100) | E16: =VLOOKUP(B8,Db!A4:V503,22,0) | F16: =VLOOKUP(B8,Db!A4:W503,23,0) | G16: =VLOOKUP(B8,Db!A4:X503,24,0) | H16: =VLOOKUP(B8,Db!A4:Y503,25,0) | I16: =VLOOKUP(B8,Db!A4:Z503,26,0) | J16: =VLOOKUP(B8,Db!A4:AA503,27,0) | K16: =IF(J16>=70,"A",IF(J16>=50,"C",IF(J16>=40,"P",IF(J16>=1,"F","NA")))) | L16: =IF(K16="A","DISTINCTION",IF(K16="C","GOOD",IF(K16="P","PASS",IF(K16="F","FAIL",IF(K16="NA","NOT APPLICABLE","")))))
B17: 4 | C17: =Db!AB2 | D17: =IF(AND(G17=0,H17=0,I17=0),"--",100) | E17: =VLOOKUP(B8,Db!A4:AB503,28,0) | F17: =VLOOKUP(B8,Db!A4:AC503,29,0) | G17: =VLOOKUP(B8,Db!A4:AD503,30,0) | H17: =VLOOKUP(B8,Db!A4:AE503,31,0) | I17: =VLOOKUP(B8,Db!A4:AF503,32,0) | J17: =VLOOKUP(B8,Db!A4:AG503,33,0) | K17: =IF(J17>=70,"A",IF(J17>=50,"C",IF(J17>=40,"P",IF(J17>=1,"F","NA")))) | L17: =IF(K17="A","DISTINCTION",IF(K17="C","GOOD",IF(K17="P","PASS",IF(K17="F","FAIL",IF(K17="NA","NOT APPLICABLE","")))))
B18: 5 | C18: =Db!AH2 | D18: =IF(AND(G18=0,H18=0,I18=0),"--",100) | E18: =VLOOKUP(B8,Db!A4:AH503,34,0) | F18: =VLOOKUP(B8,Db!A4:AI503,35,0) | G18: =VLOOKUP(B8,Db!A4:AJ503,36,0) | H18: =VLOOKUP(B8,Db!A4:AK503,37,0) | I18: =VLOOKUP(B8,Db!A4:AL503,38,0) | J18: =VLOOKUP(B8,Db!A4:AM503,39,0) | K18: =IF(J18>=70,"A",IF(J18>=50,"C",IF(J18>=40,"P",IF(J18>=1,"F","NA")))) | L18: =IF(K18="A","DISTINCTION",IF(K18="C","GOOD",IF(K18="P","PASS",IF(K18="F","FAIL",IF(K18="NA","NOT APPLICABLE","")))))
B19: 6 | C19: =Db!AN2 | D19: =IF(AND(G19=0,H19=0,I19=0),"--",100) | E19: =VLOOKUP(B8,Db!A4:AN503,40,0) | F19: =VLOOKUP(B8,Db!A4:AO503,41,0) | G19: =VLOOKUP(B8,Db!A4:AP503,42,0) | H19: =VLOOKUP(B8,Db!A4:AQ503,43,0) | I19: =VLOOKUP(B8,Db!A4:AR503,44,0) | J19: =VLOOKUP(B8,Db!A4:AS503,45,0) | K19: =IF(J19>=70,"A",IF(J19>=50,"C",IF(J19>=40,"P",IF(J19>=1,"F","NA")))) | L19: =IF(K19="A","DISTINCTION",IF(K19="C","GOOD",IF(K19="P","PASS",IF(K19="F","FAIL",IF(K19="NA","NOT APPLICABLE","")))))
B20: 7 | C20: =Db!AT2 | D20: =IF(AND(G20=0,H20=0,I20=0),"--",100) | E20: =VLOOKUP(B8,Db!A4:AT503,46,0) | F20: =VLOOKUP(B8,Db!A4:AU503,47,0) | G20: =VLOOKUP(B8,Db!A4:AV503,48,0) | H20: =VLOOKUP(B8,Db!A4:AW503,49,0) | I20: =VLOOKUP(B8,Db!A4:AX503,50,0) | J20: =VLOOKUP(B8,Db!A4:AY503,51,0) | K20: =IF(J20>=70,"A",IF(J20>=50,"C",IF(J20>=40,"P",IF(J20>=1,"F","NA")))) | L20: =IF(K20="A","DISTINCTION",IF(K20="C","GOOD",IF(K20="P","PASS",IF(K20="F","FAIL",IF(K20="NA","NOT APPLICABLE","")))))
B21: 8 | C21: =Db!AZ2 | D21: =IF(AND(G21=0,H21=0,I21=0),"--",100) | E21: =VLOOKUP(B8,Db!A4:AZ503,52,0) | F21: =VLOOKUP(B8,Db!A4:BA503,53,0) | G21: =VLOOKUP(B8,Db!A4:BB503,54,0) | H21: =VLOOKUP(B8,Db!A4:BC503,55,0) | I21: =VLOOKUP(B8,Db!A4:BD503,56,0) | J21: =VLOOKUP(B8,Db!A4:BE503,57,0) | K21: =IF(J21>=70,"A",IF(J21>=50,"C",IF(J21>=40,"P",IF(J21>=1,"F","NA")))) | L21: =IF(K21="A","DISTINCTION",IF(K21="C","GOOD",IF(K21="P","PASS",IF(K21="F","FAIL",IF(K21="NA","NOT APPLICABLE","")))))
B22: 9 | C22: =Db!BF2 | D22: =IF(AND(G22=0,H22=0,I22=0),"--",100) | E22: =VLOOKUP(B8,Db!A4:BF503,58,0) | F22: =VLOOKUP(B8,Db!A4:BG503,59,0) | G22: =VLOOKUP(B8,Db!A4:BH503,60,0) | H22: =VLOOKUP(B8,Db!A4:BI503,61,0) | I22: =VLOOKUP(B8,Db!A4:BJ503,62,0) | J22: =VLOOKUP(B8,Db!A4:BK503,63,0) | K22: =IF(J22>=70,"A",IF(J22>=50,"C",IF(J22>=40,"P",IF(J22>=1,"F","NA")))) | L22: =IF(K22="A","DISTINCTION",IF(K22="C","GOOD",IF(K22="P","PASS",IF(K22="F","FAIL",IF(K22="NA","NOT APPLICABLE","")))))
B23: 10 | C23: =Db!BL2 | D23: =IF(AND(G23=0,H23=0,I23=0),"--",100) | E23: =VLOOKUP(B8,Db!A4:BL503,64,0) | F23: =VLOOKUP(B8,Db!A4:BM503,65,0) | G23: =VLOOKUP(B8,Db!A4:BN503,66,0) | H23: =VLOOKUP(B8,Db!A4:BO503,67,0) | I23: =VLOOKUP(B8,Db!A4:BP503,68,0) | J23: =VLOOKUP(B8,Db!A4:BQ503,69,0) | K23: =IF(J23>=70,"A",IF(J23>=50,"C",IF(J23>=40,"P",IF(J23>=1,"F","NA")))) | L23: =IF(K23="A","DISTINCTION",IF(K23="C","GOOD",IF(K23="P","PASS",IF(K23="F","FAIL",IF(K23="NA","NOT APPLICABLE","")))))
B24: 11 | C24: =Db!BR2 | D24: =IF(AND(G24=0,H24=0,I24=0),"--",100) | E24: =VLOOKUP(B8,Db!A4:BR503,70,0) | F24: =VLOOKUP(B8,Db!A4:BS503,71,0) | G24: =VLOOKUP(B8,Db!A4:BT503,72,0) | H24: =VLOOKUP(B8,Db!A4:BU503,73,0) | I24: =VLOOKUP(B8,Db!A4:BV503,74,0) | J24: =VLOOKUP(B8,Db!A4:BW503,75,0) | K24: =IF(J24>=70,"A",IF(J24>=50,"C",IF(J24>=40,"P",IF(J24>=1,"F","NA")))) | L24: =IF(K24="A","DISTINCTION",IF(K24="C","GOOD",IF(K24="P","PASS",IF(K24="F","FAIL",IF(K24="NA","NOT APPLICABLE","")))))
B25: 12 | C25: =Db!BX2 | D25: =IF(AND(G25=0,H25=0,I25=0),"--",100) | E25: =VLOOKUP(B8,Db!A4:BX503,76,0) | F25: =VLOOKUP(B8,Db!A4:BY503,77,0) | G25: =VLOOKUP(B8,Db!A4:BZ503,78,0) | H25: =VLOOKUP(B8,Db!A4:CA503,79,0) | I25: =VLOOKUP(B8,Db!A4:CB503,80,0) | J25: =VLOOKUP(B8,Db!A4:CC503,81,0) | K25: =IF(J25>=70,"A",IF(J25>=50,"C",IF(J25>=40,"P",IF(J25>=1,"F","NA")))) | L25: =IF(K25="A","DISTINCTION",IF(K25="C","GOOD",IF(K25="P","PASS",IF(K25="F","FAIL",IF(K25="NA","NOT APPLICABLE","")))))
B26: 13 | C26: =Db!CD2 | D26: =IF(AND(G26=0,H26=0,I26=0),"--",100) | E26: =VLOOKUP(B8,Db!A4:CD503,82,0) | F26: =VLOOKUP(B8,Db!A4:CE503,83,0) | G26: =VLOOKUP(B8,Db!A4:CF503,84,0) | H26: =VLOOKUP(B8,Db!A4:CG503,85,0) | I26: =VLOOKUP(B8,Db!A4:CH503,86,0) | J26: =VLOOKUP(B8,Db!A4:CI503,87,0) | K26: =IF(J26>=70,"A",IF(J26>=50,"C",IF(J26>=40,"P",IF(J26>=1,"F","NA")))) | L26: =IF(K26="A","DISTINCTION",IF(K26="C","GOOD",IF(K26="P","PASS",IF(K26="F","FAIL",IF(K26="NA","NOT APPLICABLE","")))))
B27: 14 | C27: =Db!CJ2 | D27: =IF(AND(G27=0,H27=0,I27=0),"--",100) | E27: =VLOOKUP(B8,Db!A4:CJ503,88,0) | F27: =VLOOKUP(B8,Db!A4:CK503,89,0) | G27: =VLOOKUP(B8,Db!A4:CL503,90,0) | H27: =VLOOKUP(B8,Db!A4:CM503,91,0) | I27: =VLOOKUP(B8,Db!A4:CN503,92,0) | J27: =VLOOKUP(B8,Db!A4:CO503,93,0) | K27: =IF(J27>=70,"A",IF(J27>=50,"C",IF(J27>=40,"P",IF(J27>=1,"F","NA")))) | L27: =IF(K27="A","DISTINCTION",IF(K27="C","GOOD",IF(K27="P","PASS",IF(K27="F","FAIL",IF(K27="NA","NOT APPLICABLE","")))))
B28: 15 | C28: =Db!CP2 | D28: =IF(AND(G28=0,H28=0,I28=0),"--",100) | E28: =VLOOKUP(B8,Db!A4:CP503,94,0) | F28: =VLOOKUP(B8,Db!A4:CQ503,95,0) | G28: =VLOOKUP(B8,Db!A4:CR503,96,0) | H28: =VLOOKUP(B8,Db!A4:CS503,97,0) | I28: =VLOOKUP(B8,Db!A4:CT503,98,0) | J28: =VLOOKUP(B8,Db!A4:CU503,99,0) | K28: =IF(J28>=70,"A",IF(J28>=50,"C",IF(J28>=40,"P",IF(J28>=1,"F","NA")))) | L28: =IF(K28="A","DISTINCTION",IF(K28="C","GOOD",IF(K28="P","PASS",IF(K28="F","FAIL",IF(K28="NA","NOT APPLICABLE","")))))
B29: 16 | C29: =Db!CV2 | D29: =IF(AND(G29=0,H29=0,I29=0),"--",100) | E29: =VLOOKUP(B8,Db!A4:CV503,100,0) | F29: =VLOOKUP(B8,Db!A4:CW503,101,0) | G29: =VLOOKUP(B8,Db!A4:CX503,102,0) | H29: =VLOOKUP(B8,Db!A4:CY503,103,0) | I29: =VLOOKUP(B8,Db!A4:CZ503,104,0) | J29: =VLOOKUP(B8,Db!A4:DA503,105,0) | K29: =IF(J29>=70,"A",IF(J29>=50,"C",IF(J29>=40,"P",IF(J29>=1,"F","NA")))) | L29: =IF(K29="A","DISTINCTION",IF(K29="C","GOOD",IF(K29="P","PASS",IF(K29="F","FAIL",IF(K29="NA","NOT APPLICABLE","")))))
B30: 17 | C30: =Db!DB2 | D30: =IF(AND(G30=0,H30=0,I30=0),"--",100) | E30: =VLOOKUP(B8,Db!A4:DB503,106,0) | F30: =VLOOKUP(B8,Db!A4:DC503,107,0) | G30: =VLOOKUP(B8,Db!A4:DD503,108,0) | H30: =VLOOKUP(B8,Db!A4:DE503,109,0) | I30: =VLOOKUP(B8,Db!A4:DF503,110,0) | J30: =VLOOKUP(B8,Db!A4:DG503,111,0) | K30: =IF(J30>=70,"A",IF(J30>=50,"C",IF(J30>=40,"P",IF(J30>=1,"F","NA")))) | L30: =IF(K30="A","DISTINCTION",IF(K30="C","GOOD",IF(K30="P","PASS",IF(K30="F","FAIL",IF(K30="NA","NOT APPLICABLE","")))))
B31: TOTAL MARKS OBTAINABLE: | D31: =SUM(D14:D30) | H31: TOTAL MARKS OBTAINED: | J31: =SUM(J14:J30) | K31: % | L31: =FLOOR(J31/D31*100,0.1)
B32: GRADE INTERPRETATION ::: A: DISTINCTION C: CREDIT P: PASS F: FAIL
B33: BEHAVIOURAL (AFFECTIVE DOMAIN)
B34: PUNCTUALITY | D34: NEATNESS | E34: ATTENTIVENESS | F34: RELATIONSHIP WITH OTHERS | G34: POLITENESS | H34: RESPONSIVENESS | I34: COMMITMENT | J34: CONSISTENCY | K34: TOTAL SCORE | L34: 40
B35: =VLOOKUP(B8,Db!A4:DJ503,114,0) | D35: =VLOOKUP(B8,Db!A4:DK503,115,0) | E35: =VLOOKUP(B8,Db!A4:DL503,116,0) | F35: =VLOOKUP(B8,Db!A4:DM503,117,0) | G35: =VLOOKUP(B8,Db!A4:DN503,118,0) | H35: =VLOOKUP(B8,Db!A4:DO503,119,0) | I35: =VLOOKUP(B8,Db!A4:DP503,120,0) | J35: =VLOOKUP(B8,Db!A4:DQ503,121,0) | K35: SCORE OBTAINED | L35: =SUM(B36:J36)
B36: =IF(B35="EXCELLENT(5)",5,IF(B35="GOOD(4)",4,IF(B35="AVERAGE(3)",3,IF(B35="BELOW AVERAGE(2)",2,IF(B35="FAIR(1)",1,"--"))))) | D36: =IF(D35="EXCELLENT(5)",5,IF(D35="GOOD(4)",4,IF(D35="AVERAGE(3)",3,IF(D35="BELOW AVERAGE(2)",2,IF(D35="FAIR(1)",1,"--"))))) | E36: =IF(E35="EXCELLENT(5)",5,IF(E35="GOOD(4)",4,IF(E35="AVERAGE(3)",3,IF(E35="BELOW AVERAGE(2)",2,IF(E35="FAIR(1)",1,"--"))))) | F36: =IF(F35="EXCELLENT(5)",5,IF(F35="GOOD(4)",4,IF(F35="AVERAGE(3)",3,IF(F35="BELOW AVERAGE(2)",2,IF(F35="FAIR(1)",1,"--"))))) | G36: =IF(G35="EXCELLENT(5)",5,IF(G35="GOOD(4)",4,IF(G35="AVERAGE(3)",3,IF(G35="BELOW AVERAGE(2)",2,IF(G35="FAIR(1)",1,"--"))))) | H36: =IF(H35="EXCELLENT(5)",5,IF(H35="GOOD(4)",4,IF(H35="AVERAGE(3)",3,IF(H35="BELOW AVERAGE(2)",2,IF(H35="FAIR(1)",1,"--"))))) | I36: =IF(I35="EXCELLENT(5)",5,IF(I35="GOOD(4)",4,IF(I35="AVERAGE(3)",3,IF(I35="BELOW AVERAGE(2)",2,IF(I35="FAIR(1)",1,"--"))))) | J36: =IF(J35="EXCELLENT(5)",5,IF(J35="GOOD(4)",4,IF(J35="AVERAGE(3)",3,IF(J35="BELOW AVERAGE(2)",2,IF(J35="FAIR(1)",1,"--")))))
B37: PSYCHOMOTOR DOMAIN
B38: CRAFTS/DRAWING & PAINTING | D38: TECHNICAL SKILLS | E38: ICT SKILLS | F38: GARDENING/ FARMING SKILLS | G38: GAMES & SPORTS | H38: CREATIVITY & INITIATIVE | J38: VERBAL FLUENCY | K38: TOTAL SCORE | L38: =SUM(C49:I49)
B39: =VLOOKUP(B8,Db!A4:DT503,124,0) | D39: =VLOOKUP(B8,Db!A4:DU503,125,0) | E39: =VLOOKUP(B8,Db!A4:DV503,126,0) | F39: =VLOOKUP(B8,Db!A4:DW503,127,0) | G39: =VLOOKUP(B8,Db!A4:DX503,128,0) | H39: =VLOOKUP(B8,Db!A4:DY503,129,0) | J39: =VLOOKUP(B8,Db!A4:DZ503,130,0) | K39: SCORE OBTAINED | L39: =SUM(B40:K40)
B40: =IF(B39="EXCELLENT(5)",5,IF(B39="GOOD(4)",4,IF(B39="AVERAGE(3)",3,IF(B39="BELOW AVERAGE(2)",2,IF(B39="FAIR(1)",1,"--"))))) | D40: =IF(D39="EXCELLENT(5)",5,IF(D39="GOOD(4)",4,IF(D39="AVERAGE(3)",3,IF(D39="BELOW AVERAGE(2)",2,IF(D39="FAIR(1)",1,"--"))))) | E40: =IF(E39="EXCELLENT(5)",5,IF(E39="GOOD(4)",4,IF(E39="AVERAGE(3)",3,IF(E39="BELOW AVERAGE(2)",2,IF(E39="FAIR(1)",1,"--"))))) | F40: =IF(F39="EXCELLENT(5)",5,IF(F39="GOOD(4)",4,IF(F39="AVERAGE(3)",3,IF(F39="BELOW AVERAGE(2)",2,IF(F39="FAIR(1)",1,"--"))))) | G40: =IF(G39="EXCELLENT(5)",5,IF(G39="GOOD(4)",4,IF(G39="AVERAGE(3)",3,IF(G39="BELOW AVERAGE(2)",2,IF(G39="FAIR(1)",1,"--"))))) | H40: =IF(H39="EXCELLENT(5)",5,IF(H39="GOOD(4)",4,IF(H39="AVERAGE(3)",3,IF(H39="BELOW AVERAGE(2)",2,IF(H39="FAIR(1)",1,"--"))))) | J40: =IF(J39="EXCELLENT(5)",5,IF(J39="GOOD(4)",4,IF(J39="AVERAGE(3)",3,IF(J39="BELOW AVERAGE(2)",2,IF(J39="FAIR(1)",1,"--")))))
B41: NON-COGNITIVE ASPECTS RATING KEYS: 5-Excellent 4-Good 3-Average 2-Below Average 1-Fair
B42: Class Tutor's Comment: | D42: =VLOOKUP(B8,Db!A4:EA503,131,0) | H42: Class Tutor's Name: | I42: =VLOOKUP(B8,Db!A4:EC503,133,0)
B43: Principal´s Comment: | D43: =VLOOKUP(B8,Db!A4:EB503,132,0) | J43: Parent Signature:
B44: Principal´s Signature/Stamp:
...

Sheet Db
A1: 1 | B1: 2 | C1: 3 | D1: 4 | E1: 5 | F1: 6 | G1: 7 | H1: 8 | I1: 9 | J1: 10 | K1: 11 | L1: 12 | M1: 13 | N1: 14 | O1: 15 | P1: 16 | Q1: 17 | R1: 18 | S1: 19 | T1: 20 | U1: 21 | V1: 22 | W1: 23 | X1: 24 | Y1: 25 | Z1: 26 | AA1: 27 | AB1: 28 | AC1: 29 | AD1: 30 | AE1: 31 | AF1: 32 | AG1: 33 | AH1: 34 | AI1: 35 | AJ1: 36 | AK1: 37 | AL1: 38 | AM1: 39 | AN1: 40 | AO1: 41 | AP1: 42 | AQ1: 43 | AR1: 44 | AS1: 45 | AT1: 46 | AU1: 47 | AV1: 48 | AW1: 49 | AX1: 50 | AY1: 51 | AZ1: 52 | BA1: 53 | BB1: 54 | BC1: 55 | BD1: 56 | BE1: 57 | BF1: 58 | BG1: 59 | BH1: 60 | BI1: 61 | BJ1: 62 | BK1: 63 | BL1: 64 | BM1: 65 | BN1: 66 | BO1: 67 | BP1: 68 | BQ1: 69 | BR1: 70 | BS1: 71 | BT1: 72 | BU1: 73 | BV1: 74 | BW1: 75 | BX1: 76 | BY1: 77 | BZ1: 78 | CA1: 79 | CB1: 80 | CC1: 81 | CD1: 82 | CE1: 83 | CF1: 84 | CG1: 85 | CH1: 86 | CI1: 87 | CJ1: 88 | CK1: 89 | CL1: 90 | CM1: 91 | CN1: 92 | CO1: 93 | CP1: 94 | CQ1: 95 | CR1: 96 | CS1: 97 | CT1: 98 | CU1: 99 | CV1: 100 | CW1: 101 | CX1: 102 | CY1: 103 | CZ1: 104 | DA1: 105 | DB1: 106 | DC1: 107 | DD1: 108 | DE1: 109 | DF1: 110 | DG1: 111 | DH1: 112 | DI1: 113 | DJ1: 114 | DK1: 115 | DL1: 116 | DM1: 117 | DN1: 118 | DO1: 119 | DP1: 120 | DQ1: 121 | DR1: 122 | DS1: 123 | DT1: 124 | DU1: 125 | DV1: 126 | DW1: 127 | DX1: 128 | DY1: 129 | DZ1: 130 | EA1: 131 | EB1: 132 | EC1: 133 | ED1: 134
J2: General Mathematics | P2: English Language | V2: Basic Science | AB2: Basic Technology | AH2: Business Studies | AN2: CCA | AT2: Social Studies | AZ2: Agriculture-Science | BF2: Yoruba | BL2: PHE | BR2: Home-Economics | BX2: Civic Education | CD2: Computer Studies | CJ2: History | CP2: Islamic Studies | CV2: C.R.S | DB2: French | DJ2: AFFECTIVE DOMAIN | DT2: PSYCHOMOTOR DOMAIN
A3: S/N | B3: Name | C3: Admission Number | D3: Gender | E3: Class | F3: NO OF STUDENTS IN CLASS | G3: NO OF TIMES SCHOOL OPENED | H3: NO OF TIMES PRESENT | I3: NO OF TIMES ABSENT | J3: 3RD TERM C.A. (30%) | K3: 3RD TERM EXAM (70%) | L3: 3RD TERM TOTAL (100%) | M3: 2ND TERM TOTAL (100%) | N3: 1ST TERM TOTAL (100%) | O3: AVERAGE SCORE | P3: 3RD TERM C.A. (30%) | Q3: 3RD TERM EXAM (70%) | R3: 3RD TERM TOTAL (100%) | S3: 2ND TERM TOTAL (100%) | T3: 1ST TERM TOTAL (100%) | U3: AVERAGE SCORE | V3: 3RD TERM C.A. (30%) | W3: 3RD TERM EXAM (70%) | X3: 3RD TERM TOTAL (100%) | Y3: 2ND TERM TOTAL (100%) | Z3: 1ST TERM TOTAL (100%) | AA3: AVERAGE SCORE | AB3: 3RD TERM C.A. (30%) | AC3: 3RD TERM EXAM (70%) | AD3: 3RD TERM TOTAL (100%) | AE3: 2ND TERM TOTAL (100%) | AF3: 1ST TERM TOTAL (100%) | AG3: AVERAGE SCORE | AH3: 3RD TERM C.A. (30%) | AI3: 3RD TERM EXAM (70%) | AJ3: 3RD TERM TOTAL (100%) | AK3: 2ND TERM TOTAL (100%) | AL3: 1ST TERM TOTAL (100%) | AM3: AVERAGE SCORE | AN3: 3RD TERM C.A. (30%) | AO3: 3RD TERM EXAM (70%) | AP3: 3RD TERM TOTAL (100%) | AQ3: 2ND TERM TOTAL (100%) | AR3: 1ST TERM TOTAL (100%) | AS3: AVERAGE SCORE | AT3: 3RD TERM C.A. (30%) | AU3: 3RD TERM EXAM (70%) | AV3: 3RD TERM TOTAL (100%) | AW3: 2ND TERM TOTAL (100%) | AX3: 1ST TERM TOTAL (100%) | AY3: AVERAGE SCORE | AZ3: 3RD TERM C.A. (30%) | BA3: 3RD TERM EXAM (70%) | BB3: 3RD TERM TOTAL (100%) | BC3: 2ND TERM TOTAL (100%) | BD3: 1ST TERM TOTAL (100%) | BE3: AVERAGE SCORE | BF3: 3RD TERM C.A. (30%) | BG3: 3RD TERM EXAM (70%) | BH3: 3RD TERM TOTAL (100%) | BI3: 2ND TERM TOTAL (100%) | BJ3: 1ST TERM TOTAL (100%) | BK3: AVERAGE SCORE | BL3: 3RD TERM C.A. (30%) | BM3: 3RD TERM EXAM (70%) | BN3: 3RD TERM TOTAL (100%) | BO3: 2ND TERM TOTAL (100%) | BP3: 1ST TERM TOTAL (100%) | BQ3: AVERAGE SCORE | BR3: 3RD TERM C.A. (30%) | BS3: 3RD TERM EXAM (70%) | BT3: 3RD TERM TOTAL (100%) | BU3: 2ND TERM TOTAL (100%) | BV3: 1ST TERM TOTAL (100%) | BW3: AVERAGE SCORE | BX3: 3RD TERM C.A. (30%) | BY3: 3RD TERM EXAM (70%) | BZ3: 3RD TERM TOTAL (100%) | CA3: 2ND TERM TOTAL (100%) | CB3: 1ST TERM TOTAL (100%) | CC3: AVERAGE SCORE | CD3: 3RD TERM C.A. (30%) | CE3: 3RD TERM EXAM (70%) | CF3: 3RD TERM TOTAL (100%) | CG3: 2ND TERM TOTAL (100%) | CH3: 1ST TERM TOTAL (100%) | CI3: AVERAGE SCORE | CJ3: 3RD TERM C.A. (30%) | CK3: 3RD TERM EXAM (70%) | CL3: 3RD TERM TOTAL (100%) | CM3: 2ND TERM TOTAL (100%) | CN3: 1ST TERM TOTAL (100%) | CO3: AVERAGE SCORE | CP3: 3RD TERM C.A. (30%) | CQ3: 3RD TERM EXAM (70%) | CR3: 3RD TERM TOTAL (100%) | CS3: 2ND TERM TOTAL (100%) | CT3: 1ST TERM TOTAL (100%) | CU3: AVERAGE SCORE | CV3: 3RD TERM C.A. (30%) | CW3: 3RD TERM EXAM (70%) | CX3: 3RD TERM TOTAL (100%) | CY3: 2ND TERM TOTAL (100%) | CZ3: 1ST TERM TOTAL (100%) | DA3: AVERAGE SCORE | DB3: 3RD TERM C.A. (30%) | DC3: 3RD TERM EXAM (70%) | DD3: 3RD TERM TOTAL (100%) | DE3: 2ND TERM TOTAL (100%) | DF3: 1ST TERM TOTAL (100%) | DG3: AVERAGE SCORE | DH3: TOTAL SCORE | DI3: POSITION | DJ3: PUNCTUALITY | DK3: NEATNESS | DL3: ATTENTIVENESS | DM3: RELATIONSHIP WITH OTHERS | DN3: POLITENESS | DO3: RESPONSIVENESS | DP3: COMMITMENT | DQ3: CONSISTENCY | DR3: ACADEMIC SESSION | DS3: TERM | DT3: CRAFTS/ DRAWING & PAINTING | DU3: TECHNICAL SKILLS | DV3: ICT SKILLS | DW3: GARDENING/ FARMING SKILLS | DX3: GAMES & SPORTS | DY3: CREATIVITY & INITIATIVE | DZ3: VERBAL FLUENCY | EA3: CLASS TUTORS COMMENT | EB3: PRINCIPAL'S COMMENT | EC3: TUTOR'S NAME | ED3: NEXT TERM BEGINS
A4: 1 | B4: ADEROGBA BLESSING A. | C4: 1800 | D4: Male | E4: JSS 2C | F4: 31 | G4: 122 | H4: 108 | I4: =G4-H4 | J4: 24 | K4: 24 | L4: =SUM(J4:K4) | M4: 23 | N4: 28 | O4: =IF(AND(L4=0,M4=0,N4=0),0,IF(AND(L4=0,M4=0),N4/1,IF(AND(L4=0,N4=0),M4/1,IF(AND(M4=0,N4=0),L4/1,IF(L4=0,FLOOR((M4+N4)/2,0.1),IF(M4=0,(L4+N4)/2,IF(N4=0,(M4+L4)/2,FLOOR(((L4+M4+N4)/3),0.1)))))))) | P4: 13 | Q4: 27 | R4: =SUM(P4:Q4) | S4: 34 | T4: 46 | U4: =IF(AND(R4=0,S4=0,T4=0),0,IF(AND(R4=0,S4=0),T4/1,IF(AND(R4=0,T4=0),S4/1,IF(AND(S4=0,T4=0),R4/1,IF(R4=0,FLOOR((S4+T4)/2,0.1),IF(S4=0,(R4+T4)/2,IF(T4=0,(S4+R4)/2,FLOOR(((R4+S4+T4)/3),0.1)))))))) | V4: 21 | W4: 12 | X4: =SUM(V4:W4) | Y4: 47 | Z4: 40 | AA4: =IF(AND(X4=0,Y4=0,Z4=0),0,IF(AND(X4=0,Y4=0),Z4/1,IF(AND(X4=0,Z4=0),Y4/1,IF(AND(Y4=0,Z4=0),X4/1,IF(X4=0,FLOOR((Y4+Z4)/2,0.1),IF(Y4=0,(X4+Z4)/2,IF(Z4=0,(Y4+X4)/2,FLOOR(((X4+Y4+Z4)/3),0.1)))))))) | AB4: 18 | AC4: 41 | AD4: =SUM(AB4:AC4) | AE4: 35 | AF4: 47 | AG4: =IF(AND(AD4=0,AE4=0,AF4=0),0,IF(AND(AD4=0,AE4=0),AF4/1,IF(AND(AD4=0,AF4=0),AE4/1,IF(AND(AE4=0,AF4=0),AD4/1,IF(AD4=0,FLOOR((AE4+AF4)/2,0.1),IF(AE4=0,(AD4+AF4)/2,IF(AF4=0,(AE4+AD4)/2,FLOOR(((AD4+AE4+AF4)/3),0.1)))))))) | AH4: 17 | AI4: 30 | AJ4: =SUM(AH4:AI4) | AK4: 43 | AL4: 34 | AM4: =IF(AND(AJ4=0,AK4=0,AL4=0),0,IF(AND(AJ4=0,AK4=0),AL4/1,IF(AND(AJ4=0,AL4=0),AK4/1,IF(AND(AK4=0,AL4=0),AJ4/1,IF(AJ4=0,FLOOR((AK4+AL4)/2,0.1),IF(AK4=0,(AJ4+AL4)/2,IF(AL4=0,(AK4+AJ4)/2,FLOOR(((AJ4+AK4+AL4)/3),0.1)))))))) | AP4: =SUM(AN4:AO4) | AS4: =IF(AND(AP4=0,AQ4=0,AR4=0),0,IF(AND(AP4=0,AQ4=0),AR4/1,IF(AND(AP4=0,AR4=0),AQ4/1,IF(AND(AQ4=0,AR4=0),AP4/1,IF(AP4=0,FLOOR((AQ4+AR4)/2,0.1),IF(AQ4=0,(AP4+AR4)/2,IF(AR4=0,(AQ4+AP4)/2,FLOOR(((AP4+AQ4+AR4)/3),0.1)))))))) | AT4: 30 | AU4: 27 | AV4: =SUM(AT4:AU4) | AW4: 37 | AX4: 49 | AY4: =IF(AND(AV4=0,AW4=0,AX4=0),0,IF(AND(AV4=0,AW4=0),AX4/1,IF(AND(AV4=0,AX4=0),AW4/1,IF(AND(AW4=0,AX4=0),AV4/1,IF(AV4=0,FLOOR((AW4+AX4)/2,0.1),IF(AW4=0,(AV4+AX4)/2,IF(AX4=0,(AW4+AV4)/2,FLOOR(((AV4+AW4+AX4)/3),0.1)))))))) | AZ4: 22 | BA4: 32 | BB4: =SUM(AZ4:BA4) | BC4: 49 | BD4: 52 | BE4: =IF(AND(BB4=0,BC4=0,BD4=0),0,IF(AND(BB4=0,BC4=0),BD4/1,IF(AND(BB4=0,BD4=0),BC4/1,IF(AND(BC4=0,BD4=0),BB4/1,IF(BB4=0,FLOOR((BC4+BD4)/2,0.1),IF(BC4=0,(BB4+BD4)/2,IF(BD4=0,(BC4+BB4)/2,FLOOR(((BB4+BC4+BD4)/3),0.1)))))))) | BF4: 17 | BG4: 40 | BH4: =SUM(BF4:BG4) | BI4: 49 | BJ4: 34 | BK4: =IF(AND(BH4=0,BI4=0,BJ4=0),0,IF(AND(BH4=0,BI4=0),BJ4/1,IF(AND(BH4=0,BJ4=0),BI4/1,IF(AND(BI4=0,BJ4=0),BH4/1,IF(BH4=0,FLOOR((BI4+BJ4)/2,0.1),IF(BI4=0,(BH4+BJ4)/2,IF(BJ4=0,(BI4+BH4)/2,FLOOR(((BH4+BI4+BJ4)/3),0.1)))))))) | BL4: 17 | BM4: 33 | BN4: =SUM(BL4:BM4) | BO4: 31 | BP4: 51 | BQ4: =IF(AND(BN4=0,BO4=0,BP4=0),0,IF(AND(BN4=0,BO4=0),BP4/1,IF(AND(BN4=0,BP4=0),BO4/1,IF(AND(BO4=0,BP4=0),BN4/1,IF(BN4=0,FLOOR((BO4+BP4)/2,0.1),IF(BO4=0,(BN4+BP4)/2,IF(BP4=0,(BO4+BN4)/2,FLOOR(((BN4+BO4+BP4)/3),0.1)))))))) | BT4: =SUM(BR4:BS4) | BW4: =IF(AND(BT4=0,BU4=0,BV4=0),0,IF(AND(BT4=0,BU4=0),BV4/1,IF(AND(BT4=0,BV4=0),BU4/1,IF(AND(BU4=0,BV4=0),BT4/1,IF(BT4=0,FLOOR((BU4+BV4)/2,0.1),IF(BU4=0,(BT4+BV4)/2,IF(BV4=0,(BU4+BT4)/2,FLOOR(((BT4+BU4+BV4)/3),0.1)))))))) | BX4: 20 | BY4: 58 | BZ4: =SUM(BX4:BY4) | CA4: 53 | CB4: 46 | CC4: =IF(AND(BZ4=0,CA4=0,CB4=0),0,IF(AND(BZ4=0,CA4=0),CB4/1,IF(AND(BZ4=0,CB4=0),CA4/1,IF(AND(CA4=0,CB4=0),BZ4/1,IF(BZ4=0,FLOOR((CA4+CB4)/2,0.1),IF(CA4=0,(BZ4+CB4)/2,IF(CB4=0,(CA4+BZ4)/2,FLOOR(((BZ4+CA4+CB4)/3),0.1)))))))) | CD4: 15 | CE4: 44 | CF4: =SUM(CD4:CE4) | CG4: 27 | CH4: 31 | CI4: =IF(AND(CF4=0,CG4=0,CH4=0),0,IF(AND(CF4=0,CG4=0),CH4/1,IF(AND(CF4=0,CH4=0),CG4/1,IF(AND(CG4=0,CH4=0),CF4/1,IF(CF4=0,FLOOR((CG4+CH4)/2,0.1),IF(CG4=0,(CF4+CH4)/2,IF(CH4=0,(CG4+CF4)/2,FLOOR(((CF4+CG4+CH4)/3),0.1)))))))) | CL4: =SUM(CJ4:CK4) | CO4: =IF(AND(CL4=0,CM4=0,CN4=0),0,IF(AND(CL4=0,CM4=0),CN4/1,IF(AND(CL4=0,CN4=0),CM4/1,IF(AND(CM4=0,CN4=0),CL4/1,IF(CL4=0,FLOOR((CM4+CN4)/2,0.1),IF(CM4=0,(CL4+CN4)/2,IF(CN4=0,(CM4+CL4)/2,FLOOR(((CL4+CM4+CN4)/3),0.1)))))))) | CR4: =SUM(CP4:CQ4) | CU4: =IF(AND(CR4=0,CS4=0,CT4=0),0,IF(AND(CR4=0,CS4=0),CT4/1,IF(AND(CR4=0,CT4=0),CS4/1,IF(AND(CS4=0,CT4=0),CR4/1,IF(CR4=0,FLOOR((CS4+CT4)/2,0.1),IF(CS4=0,(CR4+CT4)/2,IF(CT4=0,(CS4+CR4)/2,FLOOR(((CR4+CS4+CT4)/3),0.1)))))))) | CV4: 30 | CW4: 70 | CX4: =SUM(CV4:CW4) | CY4: 59 | CZ4: 56 | DA4: =IF(AND(CX4=0,CY4=0,CZ4=0),0,IF(AND(CX4=0,CY4=0),CZ4/1,IF(AND(CX4=0,CZ4=0),CY4/1,IF(AND(CY4=0,CZ4=0),CX4/1,IF(CX4=0,FLOOR((CY4+CZ4)/2,0.1),IF(CY4=0,(CX4+CZ4)/2,IF(CZ4=0,(CY4+CX4)/2,FLOOR(((CX4+CY4+CZ4)/3),0.1)))))))) | DD4: =SUM(DB4:DC4) | DG4: =IF(AND(DD4=0,DE4=0,DF4=0),0,IF(AND(DD4=0,DE4=0),DF4/1,IF(AND(DD4=0,DF4=0),DE4/1,IF(AND(DE4=0,DF4=0),DD4/1,IF(DD4=0,FLOOR((DE4+DF4)/2,0.1),IF(DE4=0,(DD4+DF4)/2,IF(DF4=0,(DE4+DD4)/2,FLOOR(((DD4+DE4+DF4)/3),0.1)))))))) | DH4: =SUM(O4,U4,AA4,AG4,AM4,AS4,AY4,BE4,BK4,BQ4,BW4,CC4,CI4,CO4,CU4,DA4,DG4) | DI4: =RANK(DH4,DH4:DH503,0) | DJ4: EXCELLENT(5) | DK4: GOOD(4) | DL4: EXCELLENT(5) | DM4: EXCELLENT(5) | DN4: GOOD(4) | DO4: GOOD(4) | DP4: GOOD(4) | DQ4: GOOD(4) | DR4: 2024/2025 | DS4: THIRD | DT4: GOOD(4) | DU4: GOOD(4) | DV4: GOOD(4) | DW4: GOOD(4) | DX4: GOOD(4) | DY4: GOOD(4) | DZ4: GOOD(4) | EA4: Shows consistent effort and improvement in academic work. | EB4: Promoted to JSS3 | EC4: MR. JIMOH WASIU OLATUNDE | ED4: Next Term Begins on Monday, 15th September, 2025
A5: 2 | B5: AFOLABI MATTHEW | C5: 1849 | D5: Male | E5: JSS 2C | F5: 31 | G5: 122 | H5: 116 | I5: =G5-H5 | J5: 18 | K5: 18 | L5: =SUM(J5:K5) | M5: 33 | N5: 30 | O5: =IF(AND(L5=0,M5=0,N5=0),0,IF(AND(L5=0,M5=0),N5/1,IF(AND(L5=0,N5=0),M5/1,IF(AND(M5=0,N5=0),L5/1,IF(L5=0,FLOOR((M5+N5)/2,0.1),IF(M5=0,(L5+N5)/2,IF(N5=0,(M5+L5)/2,FLOOR(((L5+M5+N5)/3),0.1)))))))) | P5: 13 | Q5: 26 | R5: =SUM(P5:Q5) | S5: 60 | T5: 19 | U5: =IF(AND(R5=0,S5=0,T5=0),0,IF(AND(R5=0,S5=0),T5/1,IF(AND(R5=0,T5=0),S5/1,IF(AND(S5=0,T5=0),R5/1,IF(R5=0,FLOOR((S5+T5)/2,0.1),IF(S5=0,(R5+T5)/2,IF(T5=0,(S5+R5)/2,FLOOR(((R5+S5+T5)/3),0.1)))))))) | V5: 22 | W5: 20 | X5: =SUM(V5:W5) | Y5: 51 | Z5: 46 | AA5: =IF(AND(X5=0,Y5=0,Z5=0),0,IF(AND(X5=0,Y5=0),Z5/1,IF(AND(X5=0,Z5=0),Y5/1,IF(AND(Y5=0,Z5=0),X5/1,IF(X5=0,FLOOR((Y5+Z5)/2,0.1),IF(Y5=0,(X5+Z5)/2,IF(Z5=0,(Y5+X5)/2,FLOOR(((X5+Y5+Z5)/3),0.1)))))))) | AB5: 25 | AC5: 38 | AD5: =SUM(AB5:AC5) | AE5: 61 | AF5: 62 | AG5: =IF(AND(AD5=0,AE5=0,AF5=0),0,IF(AND(AD5=0,AE5=0),AF5/1,IF(AND(AD5=0,AF5=0),AE5/1,IF(AND(AE5=0,AF5=0),AD5/1,IF(AD5=0,FLOOR((AE5+AF5)/2,0.1),IF(AE5=0,(AD5+AF5)/2,IF(AF5=0,(AE5+AD5)/2,FLOOR(((AD5+AE5+AF5)/3),0.1)))))))) | AH5: 16 | AI5: 27 | AJ5: =SUM(AH5:AI5) | AK5: 47 | AL5: 35 | AM5: =IF(AND(AJ5=0,AK5=0,AL5=0),0,IF(AND(AJ5=0,AK5=0),AL5/1,IF(AND(AJ5=0,AL5=0),AK5/1,IF(AND(AK5=0,AL5=0),AJ5/1,IF(AJ5=0,FLOOR((AK5+AL5)/2,0.1),IF(AK5=0,(AJ5+AL5)/2,IF(AL5=0,(AK5+AJ5)/2,FLOOR(((AJ5+AK5+AL5)/3),0.1)))))))) | AP5: =SUM(AN5:AO5) | AS5: =IF(AND(AP5=0,AQ5=0,AR5=0),0,IF(AND(AP5=0,AQ5=0),AR5/1,IF(AND(AP5=0,AR5=0),AQ5/1,IF(AND(AQ5=0,AR5=0),AP5/1,IF(AP5=0,FLOOR((AQ5+AR5)/2,0.1),IF(AQ5=0,(AP5+AR5)/2,IF(AR5=0,(AQ5+AP5)/2,FLOOR(((AP5+AQ5+AR5)/3),0.1)))))))) | AT5: 21 | AU5: 35 | AV5: =SUM(AT5:AU5) | AW5: 40 | AX5: 31 | AY5: =IF(AND(AV5=0,AW5=0,AX5=0),0,IF(AND(AV5=0,AW5=0),AX5/1,IF(AND(AV5=0,AX5=0),AW5/1,IF(AND(AW5=0,AX5=0),AV5/1,IF(AV5=0,FLOOR((AW5+AX5)/2,0.1),IF(AW5=0,(AV5+AX5)/2,IF(AX5=0,(AW5+AV5)/2,FLOOR(((AV5+AW5+AX5)/3),0.1)))))))) | AZ5: 22 | BA5: 30 | BB5: =SUM(AZ5:BA5) | BC5: 41 | BD5: 46 | BE5: =IF(AND(BB5=0,BC5=0,BD5=0),0,IF(AND(BB5=0,BC5=0),BD5/1,IF(AND(BB5=0,BD5=0),BC5/1,IF(AND(BC5=0,BD5=0),BB5/1,IF(BB5=0,FLOOR((BC5+BD5)/2,0.1),IF(BC5=0,(BB5+BD5)/2,IF(BD5=0,(BC5+BB5)/2,FLOOR(((BB5+BC5+BD5)/3),0.1)))))))) | BF5: 14 | BG5: 37 | BH5: =SUM(BF5:BG5) | BI5: 68 | BJ5: 28 | BK5: =IF(AND(BH5=0,BI5=0,BJ5=0),0,IF(AND(BH5=0,BI5=0),BJ5/1,IF(AND(BH5=0,BJ5=0),BI5/1,IF(AND(BI5=0,BJ5=0),BH5/1,IF(BH5=0,FLOOR((BI5+BJ5)/2,0.1),IF(BI5=0,(BH5+BJ5)/2,IF(BJ5=0,(BI5+BH5)/2,FLOOR(((BH5+BI5+BJ5)/3),0.1)))))))) | BL5: 15 | BM5: 37 | BN5: =SUM(BL5:BM5) | BO5: 27 | BP5: 54 | BQ5: =IF(AND(BN5=0,BO5=0,BP5=0),0,IF(AND(BN5=0,BO5=0),BP5/1,IF(AND(BN5=0,BP5=0),BO5/1,IF(AND(BO5=0,BP5=0),BN5/1,IF(BN5=0,FLOOR((BO5+BP5)/2,0.1),IF(BO5=0,(BN5+BP5)/2,IF(BP5=0,(BO5+BN5)/2,FLOOR(((BN5+BO5+BP5)/3),0.1)))))))) | BT5: =SUM(BR5:BS5) | BW5: =IF(AND(BT5=0,BU5=0,BV5=0),0,IF(AND(BT5=0,BU5=0),BV5/1,IF(AND(BT5=0,BV5=0),BU5/1,IF(AND(BU5=0,BV5=0),BT5/1,IF(BT5=0,FLOOR((BU5+BV5)/2,0.1),IF(BU5=0,(BT5+BV5)/2,IF(BV5=0,(BU5+BT5)/2,FLOOR(((BT5+BU5+BV5)/3),0.1)))))))) | BX5: 15 | BY5: 60 | BZ5: =SUM(BX5:BY5) | CA5: 45 | CB5: 50 | CC5: =IF(AND(BZ5=0,CA5=0,CB5=0),0,IF(AND(BZ5=0,CA5=0),CB5/1,IF(AND(BZ5=0,CB5=0),CA5/1,IF(AND(CA5=0,CB5=0),BZ5/1,IF(BZ5=0,FLOOR((CA5+CB5)/2,0.1),IF(CA5=0,(BZ5+CB5)/2,IF(CB5=0,(CA5+BZ5)/2,FLOOR(((BZ5+CA5+CB5)/3),0.1)))))))) | CD5: 15 | CE5: 47 | CF5: =SUM(CD5:CE5) | CG5: 38 | CH5: 42 | CI5: =IF(AND(CF5=0,CG5=0,CH5=0),0,IF(AND(CF5=0,CG5=0),CH5/1,IF(AND(CF5=0,CH5=0),CG5/1,IF(AND(CG5=0,CH5=0),CF5/1,IF(CF5=0,FLOOR((CG5+CH5)/2,0.1),IF(CG5=0,(CF5+CH5)/2,IF(CH5=0,(CG5+CF5)/2,FLOOR(((CF5+CG5+CH5)/3),0.1)))))))) | CL5: =SUM(CJ5:CK5) | CO5: =IF(AND(CL5=0,CM5=0,CN5=0),0,IF(AND(CL5=0,CM5=0),CN5/1,IF(AND(CL5=0,CN5=0),CM5/1,IF(AND(CM5=0,CN5=0),CL5/1,IF(CL5=0,FLOOR((CM5+CN5)/2,0.1),IF(CM5=0,(CL5+CN5)/2,IF(CN5=0,(CM5+CL5)/2,FLOOR(((CL5+CM5+CN5)/3),0.1)))))))) | CR5: =SUM(CP5:CQ5) | CU5: =IF(AND(CR5=0,CS5=0,CT5=0),0,IF(AND(CR5=0,CS5=0),CT5/1,IF(AND(CR5=0,CT5=0),CS5/1,IF(AND(CS5=0,CT5=0),CR5/1,IF(CR5=0,FLOOR((CS5+CT5)/2,0.1),IF(CS5=0,(CR5+CT5)/2,IF(CT5=0,(CS5+CR5)/2,FLOOR(((CR5+CS5+CT5)/3),0.1)))))))) | CV5: 30 | CW5: 26 | CX5: =SUM(CV5:CW5) | CY5: 47 | CZ5: 32 | DA5: =IF(AND(CX5=0,CY5=0,CZ5=0),0,IF(AND(CX5=0,CY5=0),CZ5/1,IF(AND(CX5=0,CZ5=0),CY5/1,IF(AND(CY5=0,CZ5=0),CX5/1,IF(CX5=0,FLOOR((CY5+CZ5)/2,0.1),IF(CY5=0,(CX5+CZ5)/2,IF(CZ5=0,(CY5+CX5)/2,FLOOR(((CX5+CY5+CZ5)/3),0.1)))))))) | DD5: =SUM(DB5:DC5) | DG5: =IF(AND(DD5=0,DE5=0,DF5=0),0,IF(AND(DD5=0,DE5=0),DF5/1,IF(AND(DD5=0,DF5=0),DE5/1,IF(AND(DE5=0,DF5=0),DD5/1,IF(DD5=0,FLOOR((DE5+DF5)/2,0.1),IF(DE5=0,(DD5+DF5)/2,IF(DF5=0,(DE5+DD5)/2,FLOOR(((DD5+DE5+DF5)/3),0.1)))))))) | DH5: =SUM(O5,U5,AA5,AG5,AM5,AS5,AY5,BE5,BK5,BQ5,BW5,CC5,CI5,CO5,CU5,DA5,DG5) | DI5: =RANK(DH5,DH$4:DH$503) | DJ5: EXCELLENT(5) | DK5: GOOD(4) | DL5: EXCELLENT(5) | DM5: EXCELLENT(5) | DN5: GOOD(4) | DO5: GOOD(4) | DP5: GOOD(4) | DQ5: GOOD(4) | DR5: 2024/2025 | DS5: THIRD | DT5: GOOD(4) | DU5: GOOD(4) | DV5: GOOD(4) | DW5: GOOD(4) | DX5: GOOD(4) | DY5: GOOD(4) | DZ5: GOOD(4) | EA5: Consistently well-behaved and sets a good example for peers. | EB5: Promoted to JSS3 | EC5: MR. JIMOH WASIU OLATUNDE | ED5: Next Term Begins on Monday, 15th September, 2026
A6: 3 | B6: AKEEM OPEYEMI ABIKE | C6: 1833 | D6: Female | E6: JSS 2C | F6: 31 | G6: 122 | H6: 96 | I6: =G6-H6 | J6: 30 | K6: 42 | L6: =SUM(J6:K6) | M6: 58 | N6: 59 | O6: =IF(AND(L6=0,M6=0,N6=0),0,IF(AND(L6=0,M6=0),N6/1,IF(AND(L6=0,N6=0),M6/1,IF(AND(M6=0,N6=0),L6/1,IF(L6=0,FLOOR((M6+N6)/2,0.1),IF(M6=0,(L6+N6)/2,IF(N6=0,(M6+L6)/2,FLOOR(((L6+M6+N6)/3),0.1)))))))) | P6: 22 | Q6: 44 | R6: =SUM(P6:Q6) | S6: 71 | T6: 62 | U6: =IF(AND(R6=0,S6=0,T6=0),0,IF(AND(R6=0,S6=0),T6/1,IF(AND(R6=0,T6=0),S6/1,IF(AND(S6=0,T6=0),R6/1,IF(R6=0,FLOOR((S6+T6)/2,0.1),IF(S6=0,(R6+T6)/2,IF(T6=0,(S6+R6)/2,FLOOR(((R6+S6+T6)/3),0.1)))))))) | V6: 19 | W6: 27 | X6: =SUM(V6:W6) | Y6: 49 | Z6: 48 | AA6: =IF(AND(X6=0,Y6=0,Z6=0),0,IF(AND(X6=0,Y6=0),Z6/1,IF(AND(X6=0,Z6=0),Y6/1,IF(AND(Y6=0,Z6=0),X6/1,IF(X6=0,FLOOR((Y6+Z6)/2,0.1),IF(Y6=0,(X6+Z6)/2,IF(Z6=0,(Y6+X6)/2,FLOOR(((X6+Y6+Z6)/3),0.1)))))))) | AB6: 25 | AC6: 62 | AD6: =SUM(AB6:AC6) | AE6: 56 | AF6: 72 | AG6: =IF(AND(AD6=0,AE6=0,AF6=0),0,IF(AND(AD6=0,AE6=0),AF6/1,IF(AND(AD6=0,AF6=0),AE6/1,IF(AND(AE6=0,AF6=0),AD6/1,IF(AD6=0,FLOOR((AE6+AF6)/2,0.1),IF(AE6=0,(AD6+AF6)/2,IF(AF6=0,(AE6+AD6)/2,FLOOR(((AD6+AE6+AF6)/3),0.1)))))))) | AH6: 19 | AI6: 41 | AJ6: =SUM(AH6:AI6) | AK6: 40 | AL6: 47 | AM6: =IF(AND(AJ6=0,AK6=0,AL6=0),0,IF(AND(AJ6=0,AK6=0),AL6/1,IF(AND(AJ6=0,AL6=0),AK6/1,IF(AND(AK6=0,AL6=0),AJ6/1,IF(AJ6=0,FLOOR((AK6+AL6)/2,0.1),IF(AK6=0,(AJ6+AL6)/2,IF(AL6=0,(AK6+AJ6)/2,FLOOR(((AJ6+AK6+AL6)/3),0.1)))))))) | AP6: =SUM(AN6:AO6) | AS6: =IF(AND(AP6=0,AQ6=0,AR6=0),0,IF(AND(AP6=0,AQ6=0),AR6/1,IF(AND(AP6=0,AR6=0),AQ6/1,IF(AND(AQ6=0,AR6=0),AP6/1,IF(AP6=0,FLOOR((AQ6+AR6)/2,0.1),IF(AQ6=0,(AP6+AR6)/2,IF(AR6=0,(AQ6+AP6)/2,FLOOR(((AP6+AQ6+AR6)/3),0.1)))))))) | AT6: 20 | AU6: 43 | AV6: =SUM(AT6:AU6) | AW6: 48 | AX6: 39 | AY6: =IF(AND(AV6=0,AW6=0,AX6=0),0,IF(AND(AV6=0,AW6=0),AX6/1,IF(AND(AV6=0,AX6=0),AW6/1,IF(AND(AW6=0,AX6=0),AV6/1,IF(AV6=0,FLOOR((AW6+AX6)/2,0.1),IF(AW6=0,(AV6+AX6)/2,IF(AX6=0,(AW6+AV6)/2,FLOOR(((AV6+AW6+AX6)/3),0.1)))))))) | AZ6: 24 | BA6: 51 | BB6: =SUM(AZ6:BA6) | BC6: 54 | BD6: 64 | BE6: =IF(AND(BB6=0,BC6=0,BD6=0),0,IF(AND(BB6=0,BC6=0),BD6/1,IF(AND(BB6=0,BD6=0),BC6/1,IF(AND(BC6=0,BD6=0),BB6/1,IF(BB6=0,FLOOR((BC6+BD6)/2,0.1),IF(BC6=0,(BB6+BD6)/2,IF(BD6=0,(BC6+BB6)/2,FLOOR(((BB6+BC6+BD6)/3),0.1)))))))) | BF6: 15 | BG6: 54 | BH6: =SUM(BF6:BG6) | BI6: 63 | BJ6: 38 | BK6: =IF(AND(BH6=0,BI6=0,BJ6=0),0,IF(AND(BH6=0,BI6=0),BJ6/1,IF(AND(BH6=0,BJ6=0),BI6/1,IF(AND(BI6=0,BJ6=0),BH6/1,IF(BH6=0,FLOOR((BI6+BJ6)/2,0.1),IF(BI6=0,(BH6+BJ6)/2,IF(BJ6=0,(BI6+BH6)/2,FLOOR(((BH6+BI6+BJ6)/3),0.1)))))))) | BL6: 18 | BM6: 33 | BN6: =SUM(BL6:BM6) | BO6: 31 | BP6: 44 | BQ6: =IF(AND(BN6=0,BO6=0,BP6=0),0,IF(AND(BN6=0,BO6=0),BP6/1,IF(AND(BN6=0,BP6=0),BO6/1,IF(AND(BO6=0,BP6=0),BN6/1,IF(BN6=0,FLOOR((BO6+BP6)/2,0.1),IF(BO6=0,(BN6+BP6)/2,IF(BP6=0,(BO6+BN6)/2,FLOOR(((BN6+BO6+BP6)/3),0.1)))))))) | BT6: =SUM(BR6:BS6) | BW6: =IF(AND(BT6=0,BU6=0,BV6=0),0,IF(AND(BT6=0,BU6=0),BV6/1,IF(AND(BT6=0,BV6=0),BU6/1,IF(AND(BU6=0,BV6=0),BT6/1,IF(BT6=0,FLOOR((BU6+BV6)/2,0.1),IF(BU6=0,(BT6+BV6)/2,IF(BV6=0,(BU6+BT6)/2,FLOOR(((BT6+BU6+BV6)/3),0.1)))))))) | BX6: 21 | BY6: 49 | BZ6: =SUM(BX6:BY6) | CA6: 63 | CB6: 74 | CC6: =IF(AND(BZ6=0,CA6=0,CB6=0),0,IF(AND(BZ6=0,CA6=0),CB6/1,IF(AND(BZ6=0,CB6=0),CA6/1,IF(AND(CA6=0,CB6=0),BZ6/1,IF(BZ6=0,FLOOR((CA6+CB6)/2,0.1),IF(CA6=0,(BZ6+CB6)/2,IF(CB6=0,(CA6+BZ6)/2,FLOOR(((BZ6+CA6+CB6)/3),0.1)))))))) | CD6: 15 | CE6: 46 | CF6: =SUM(CD6:CE6) | CG6: 25 | CH6: 44 | CI6: =IF(AND(CF6=0,CG6=0,CH6=0),0,IF(AND(CF6=0,CG6=0),CH6/1,IF(AND(CF6=0,CH6=0),CG6/1,IF(AND(CG6=0,CH6=0),CF6/1,IF(CF6=0,FLOOR((CG6+CH6)/2,0.1),IF(CG6=0,(CF6+CH6)/2,IF(CH6=0,(CG6+CF6)/2,FLOOR(((CF6+CG6+CH6)/3),0.1)))))))) | CL6: =SUM(CJ6:CK6) | CO6: =IF(AND(CL6=0,CM6=0,CN6=0),0,IF(AND(CL6=0,CM6=0),CN6/1,IF(AND(CL6=0,CN6=0),CM6/1,IF(AND(CM6=0,CN6=0),CL6/1,IF(CL6=0,FLOOR((CM6+CN6)/2,0.1),IF(CM6=0,(CL6+CN6)/2,IF(CN6=0,(CM6+CL6)/2,FLOOR(((CL6+CM6+CN6)/3),0.1)))))))) | CR6: =SUM(CP6:CQ6) | CU6: =IF(AND(CR6=0,CS6=0,CT6=0),0,IF(AND(CR6=0,CS6=0),CT6/1,IF(AND(CR6=0,CT6=0),CS6/1,IF(AND(CS6=0,CT6=0),CR6/1,IF(CR6=0,FLOOR((CS6+CT6)/2,0.1),IF(CS6=0,(CR6+CT6)/2,IF(CT6=0,(CS6+CR6)/2,FLOOR(((CR6+CS6+CT6)/3),0.1)))))))) | CV6: 30 | CW6: 43 | CX6: =SUM(CV6:CW6) | CY6: 23 | CZ6: 30 | DA6: =IF(AND(CX6=0,CY6=0,CZ6=0),0,IF(AND(CX6=0,CY6=0),CZ6/1,IF(AND(CX6=0,CZ6=0),CY6/1,IF(AND(CY6=0,CZ6=0),CX6/1,IF(CX6=0,FLOOR((CY6+CZ6)/2,0.1),IF(CY6=0,(CX6+CZ6)/2,IF(CZ6=0,(CY6+CX6)/2,FLOOR(((CX6+CY6+CZ6)/3),0.1)))))))) | DD6: =SUM(DB6:DC6) | DG6: =IF(AND(DD6=0,DE6=0,DF6=0),0,IF(AND(DD6=0,DE6=0),DF6/1,IF(AND(DD6=0,DF6=0),DE6/1,IF(AND(DE6=0,DF6=0),DD6/1,IF(DD6=0,FLOOR((DE6+DF6)/2,0.1),IF(DE6=0,(DD6+DF6)/2,IF(DF6=0,(DE6+DD6)/2,FLOOR(((DD6+DE6+DF6)/3),0.1)))))))) | DH6: =SUM(O6,U6,AA6,AG6,AM6,AS6,AY6,BE6,BK6,BQ6,BW6,CC6,CI6,CO6,CU6,DA6,DG6) | DI6: =RANK(DH6,DH$4:DH$503) | DJ6: GOOD(4) | DK6: GOOD(4) | DL6: EXCELLENT(5) | DM6: EXCELLENT(5) | DN6: GOOD(4) | DO6: GOOD(4) | DP6: GOOD(4) | DQ6: GOOD(4) | DR6: 2024/2025 | DS6: THIRD | DT6: GOOD(4) | DU6: GOOD(4) | DV6: GOOD(4) | DW6: GOOD(4) | DX6: GOOD(4) | DY6: GOOD(4) | DZ6: GOOD(4) | EA6: Is a quiet student but attentive and engaged. | EB6: Promoted to JSS3 | EC6: MR. JIMOH WASIU OLATUNDE | ED6: Next Term Begins on Monday, 15th September, 2027
A7: 4 | B7: ALABI ELIZABETH D. | C7: 1851 | D7: Female | E7: JSS 2C | F7: 31 | G7: 122 | H7: 96 | I7: =G7-H7 | J7: 27 | K7: 29 | L7: =SUM(J7:K7) | M7: 39 | N7: 31 | O7: =IF(AND(L7=0,M7=0,N7=0),0,IF(AND(L7=0,M7=0),N7/1,IF(AND(L7=0,N7=0),M7/1,IF(AND(M7=0,N7=0),L7/1,IF(L7=0,FLOOR((M7+N7)/2,0.1),IF(M7=0,(L7+N7)/2,IF(N7=0,(M7+L7)/2,FLOOR(((L7+M7+N7)/3),0.1)))))))) | P7: 23 | Q7: 45 | R7: =SUM(P7:Q7) | S7: 74 | T7: 62 | U7: =IF(AND(R7=0,S7=0,T7=0),0,IF(AND(R7=0,S7=0),T7/1,IF(AND(R7=0,T7=0),S7/1,IF(AND(S7=0,T7=0),R7/1,IF(R7=0,FLOOR((S7+T7)/2,0.1),IF(S7=0,(R7+T7)/2,IF(T7=0,(S7+R7)/2,FLOOR(((R7+S7+T7)/3),0.1)))))))) | V7: 25 | W7: 16 | X7: =SUM(V7:W7) | Y7: 49 | Z7: 45 | AA7: =IF(AND(X7=0,Y7=0,Z7=0),0,IF(AND(X7=0,Y7=0),Z7/1,IF(AND(X7=0,Z7=0),Y7/1,IF(AND(Y7=0,Z7=0),X7/1,IF(X7=0,FLOOR((Y7+Z7)/2,0.1),IF(Y7=0,(X7+Z7)/2,IF(Z7=0,(Y7+X7)/2,FLOOR(((X7+Y7+Z7)/3),0.1)))))))) | AB7: 25 | AC7: 59 | AD7: =SUM(AB7:AC7) | AE7: 86 | AF7: 85 | AG7: =IF(AND(AD7=0,AE7=0,AF7=0),0,IF(AND(AD7=0,AE7=0),AF7/1,IF(AND(AD7=0,AF7=0),AE7/1,IF(AND(AE7=0,AF7=0),AD7/1,IF(AD7=0,FLOOR((AE7+AF7)/2,0.1),IF(AE7=0,(AD7+AF7)/2,IF(AF7=0,(AE7+AD7)/2,FLOOR(((AD7+AE7+AF7)/3),0.1)))))))) | AH7: 18 | AI7: 42 | AJ7: =SUM(AH7:AI7) | AK7: 54 | AL7: 47 | AM7: =IF(AND(AJ7=0,AK7=0,AL7=0),0,IF(AND(AJ7=0,AK7=0),AL7/1,IF(AND(AJ7=0,AL7=0),AK7/1,IF(AND(AK7=0,AL7=0),AJ7/1,IF(AJ7=0,FLOOR((AK7+AL7)/2,0.1),IF(AK7=0,(AJ7+AL7)/2,IF(AL7=0,(AK7+AJ7)/2,FLOOR(((AJ7+AK7+AL7)/3),0.1)))))))) | AP7: =SUM(AN7:AO7) | AS7: =IF(AND(AP7=0,AQ7=0,AR7=0),0,IF(AND(AP7=0,AQ7=0),AR7/1,IF(AND(AP7=0,AR7=0),AQ7/1,IF(AND(AQ7=0,AR7=0),AP7/1,IF(AP7=0,FLOOR((AQ7+AR7)/2,0.1),IF(AQ7=0,(AP7+AR7)/2,IF(AR7=0,(AQ7+AP7)/2,FLOOR(((AP7+AQ7+AR7)/3),0.1)))))))) | AT7: 30 | AU7: 30 | AV7: =SUM(AT7:AU7) | AW7: 46 | AX7: 63 | AY7: =IF(AND(AV7=0,AW7=0,AX7=0),0,IF(AND(AV7=0,AW7=0),AX7/1,IF(AND(AV7=0,AX7=0),AW7/1,IF(AND(AW7=0,AX7=0),AV7/1,IF(AV7=0,FLOOR((AW7+AX7)/2,0.1),IF(AW7=0,(AV7+AX7)/2,IF(AX7=0,(AW7+AV7)/2,FLOOR(((AV7+AW7+AX7)/3),0.1)))))))) | AZ7: 23 | BA7: 53 | BB7: =SUM(AZ7:BA7) | BC7: 67 | BD7: 72 | BE7: =IF(AND(BB7=0,BC7=0,BD7=0),0,IF(AND(BB7=0,BC7=0),BD7/1,IF(AND(BB7=0,BD7=0),BC7/1,IF(AND(BC7=0,BD7=0),BB7/1,IF(BB7=0,FLOOR((BC7+BD7)/2,0.1),IF(BC7=0,(BB7+BD7)/2,IF(BD7=0,(BC7+BB7)/2,FLOOR(((BB7+BC7+BD7)/3),0.1)))))))) | BF7: 15 | BG7: 38 | BH7: =SUM(BF7:BG7) | BI7: 53 | BJ7: 34 | BK7: =IF(AND(BH7=0,BI7=0,BJ7=0),0,IF(AND(BH7=0,BI7=0),BJ7/1,IF(AND(BH7=0,BJ7=0),BI7/1,IF(AND(BI7=0,BJ7=0),BH7/1,IF(BH7=0,FLOOR((BI7+BJ7)/2,0.1),IF(BI7=0,(BH7+BJ7)/2,IF(BJ7=0,(BI7+BH7)/2,FLOOR(((BH7+BI7+BJ7)/3),0.1)))))))) | BL7: 19 | BM7: 31 | BN7: =SUM(BL7:BM7) | BO7: 32 | BP7: 51 | BQ7: =IF(AND(BN7=0,BO7=0,BP7=0),0,IF(AND(BN7=0,BO7=0),BP7/1,IF(AND(BN7=0,BP7=0),BO7/1,IF(AND(BO7=0,BP7=0),BN7/1,IF(BN7=0,FLOOR((BO7+BP7)/2,0.1),IF(BO7=0,(BN7+BP7)/2,IF(BP7=0,(BO7+BN7)/2,FLOOR(((BN7+BO7+BP7)/3),0.1)))))))) | BT7: =SUM(BR7:BS7) | BW7: =IF(AND(BT7=0,BU7=0,BV7=0),0,IF(AND(BT7=0,BU7=0),BV7/1,IF(AND(BT7=0,BV7=0),BU7/1,IF(AND(BU7=0,BV7=0),BT7/1,IF(BT7=0,FLOOR((BU7+BV7)/2,0.1),IF(BU7=0,(BT7+BV7)/2,IF(BV7=0,(BU7+BT7)/2,FLOOR(((BT7+BU7+BV7)/3),0.1)))))))) | BX7: 23 | BY7: 63 | BZ7: =SUM(BX7:BY7) | CA7: 57 | CB7: 54 | CC7: =IF(AND(BZ7=0,CA7=0,CB7=0),0,IF(AND(BZ7=0,CA7=0),CB7/1,IF(AND(BZ7=0,CB7=0),CA7/1,IF(AND(CA7=0,CB7=0),BZ7/1,IF(BZ7=0,FLOOR((CA7+CB7)/2,0.1),IF(CA7=0,(BZ7+CB7)/2,IF(CB7=0,(CA7+BZ7)/2,FLOOR(((BZ7+CA7+CB7)/3),0.1)))))))) | CD7: 16 | CE7: 51 | CF7: =SUM(CD7:CE7) | CG7: 22 | CH7: 40 | CI7: =IF(AND(CF7=0,CG7=0,CH7=0),0,IF(AND(CF7=0,CG7=0),CH7/1,IF(AND(CF7=0,CH7=0),CG7/1,IF(AND(CG7=0,CH7=0),CF7/1,IF(CF7=0,FLOOR((CG7+CH7)/2,0.1),IF(CG7=0,(CF7+CH7)/2,IF(CH7=0,(CG7+CF7)/2,FLOOR(((CF7+CG7+CH7)/3),0.1)))))))) | CL7: =SUM(CJ7:CK7) | CO7: =IF(AND(CL7=0,CM7=0,CN7=0),0,IF(AND(CL7=0,CM7=0),CN7/1,IF(AND(CL7=0,CN7=0),CM7/1,IF(AND(CM7=0,CN7=0),CL7/1,IF(CL7=0,FLOOR((CM7+CN7)/2,0.1),IF(CM7=0,(CL7+CN7)/2,IF(CN7=0,(CM7+CL7)/2,FLOOR(((CL7+CM7+CN7)/3),0.1)))))))) | CR7: =SUM(CP7:CQ7) | CU7: =IF(AND(CR7=0,CS7=0,CT7=0),0,IF(AND(CR7=0,CS7=0),CT7/1,IF(AND(CR7=0,CT7=0),CS7/1,IF(AND(CS7=0,CT7=0),CR7/1,IF(CR7=0,FLOOR((CS7+CT7)/2,0.1),IF(CS7=0,(CR7+CT7)/2,IF(CT7=0,(CS7+CR7)/2,FLOOR(((CR7+CS7+CT7)/3),0.1)))))))) | CV7: 30 | CW7: 26 | CX7: =SUM(CV7:CW7) | CY7: 59 | CZ7: 56 | DA7: =IF(AND(CX7=0,CY7=0,CZ7=0),0,IF(AND(CX7=0,CY7=0),CZ7/1,IF(AND(CX7=0,CZ7=0),CY7/1,IF(AND(CY7=0,CZ7=0),CX7/1,IF(CX7=0,FLOOR((CY7+CZ7)/2,0.1),IF(CY7=0,(CX7+CZ7)/2,IF(CZ7=0,(CY7+CX7)/2,FLOOR(((CX7+CY7+CZ7)/3),0.1)))))))) | DD7: =SUM(DB7:DC7) | DG7: =IF(AND(DD7=0,DE7=0,DF7=0),0,IF(AND(DD7=0,DE7=0),DF7/1,IF(AND(DD7=0,DF7=0),DE7/1,IF(AND(DE7=0,DF7=0),DD7/1,IF(DD7=0,FLOOR((DE7+DF7)/2,0.1),IF(DE7=0,(DD7+DF7)/2,IF(DF7=0,(DE7+DD7)/2,FLOOR(((DD7+DE7+DF7)/3),0.1)))))))) | DH7: =SUM(O7,U7,AA7,AG7,AM7,AS7,AY7,BE7,BK7,BQ7,BW7,CC7,CI7,CO7,CU7,DA7,DG7) | DI7: =RANK(DH7,DH$4:DH$503) | DJ7: GOOD(4) | DK7: GOOD(4) | DL7: EXCELLENT(5) | DM7: EXCELLENT(5) | DN7: GOOD(4) | DO7: GOOD(4) | DP7: GOOD(4) | DQ7: GOOD(4) | DR7: 2024/2025 | DS7: THIRD | DT7: GOOD(4) | DU7: GOOD(4) | DV7: GOOD(4) | DW7: GOOD(4) | DX7: GOOD(4) | DY7: GOOD(4) | DZ7: GOOD(4) | EA7: She is developing greater self-confidence and resilience. | EB7: Promoted to JSS3 | EC7: MR. JIMOH WASIU OLATUNDE | ED7: Next Term Begins on Monday, 15th September, 2028
A8: 5 | B8: ALABI FATIMO | C8: 1845 | D8: Female | E8: JSS 2C | F8: 31 | G8: 122 | H8: 98 | I8: =G8-H8 | J8: 16 | K8: 16 | L8: =SUM(J8:K8) | M8: 16 | N8: 31 | O8: =IF(AND(L8=0,M8=0,N8=0),0,IF(AND(L8=0,M8=0),N8/1,IF(AND(L8=0,N8=0),M8/1,IF(AND(M8=0,N8=0),L8/1,IF(L8=0,FLOOR((M8+N8)/2,0.1),IF(M8=0,(L8+N8)/2,IF(N8=0,(M8+L8)/2,FLOOR(((L8+M8+N8)/3),0.1)))))))) | P8: 11 | Q8: 23 | R8: =SUM(P8:Q8) | S8: 8 | T8: 60 | U8: =IF(AND(R8=0,S8=0,T8=0),0,IF(AND(R8=0,S8=0),T8/1,IF(AND(R8=0,T8=0),S8/1,IF(AND(S8=0,T8=0),R8/1,IF(R8=0,FLOOR((S8+T8)/2,0.1),IF(S8=0,(R8+T8)/2,IF(T8=0,(S8+R8)/2,FLOOR(((R8+S8+T8)/3),0.1)))))))) | V8: 25 | W8: 14 | X8: =SUM(V8:W8) | Y8: 52 | Z8: 46 | AA8: =IF(AND(X8=0,Y8=0,Z8=0),0,IF(AND(X8=0,Y8=0),Z8/1,IF(AND(X8=0,Z8=0),Y8/1,IF(AND(Y8=0,Z8=0),X8/1,IF(X8=0,FLOOR((Y8+Z8)/2,0.1),IF(Y8=0,(X8+Z8)/2,IF(Z8=0,(Y8+X8)/2,FLOOR(((X8+Y8+Z8)/3),0.1)))))))) | AB8: 25 | AC8: 32 | AD8: =SUM(AB8:AC8) | AE8: 74 | AF8: 66 | AG8: =IF(AND(AD8=0,AE8=0,AF8=0),0,IF(AND(AD8=0,AE8=0),AF8/1,IF(AND(AD8=0,AF8=0),AE8/1,IF(AND(AE8=0,AF8=0),AD8/1,IF(AD8=0,FLOOR((AE8+AF8)/2,0.1),IF(AE8=0,(AD8+AF8)/2,IF(AF8=0,(AE8+AD8)/2,FLOOR(((AD8+AE8+AF8)/3),0.1)))))))) | AH8: 23 | AI8: 46 | AJ8: =SUM(AH8:AI8) | AK8: 78 | AL8: 60 | AM8: =IF(AND(AJ8=0,AK8=0,AL8=0),0,IF(AND(AJ8=0,AK8=0),AL8/1,IF(AND(AJ8=0,AL8=0),AK8/1,IF(AND(AK8=0,AL8=0),AJ8/1,IF(AJ8=0,FLOOR((AK8+AL8)/2,0.1),IF(AK8=0,(AJ8+AL8)/2,IF(AL8=0,(AK8+AJ8)/2,FLOOR(((AJ8+AK8+AL8)/3),0.1)))))))) | AP8: =SUM(AN8:AO8) | AS8: =IF(AND(AP8=0,AQ8=0,AR8=0),0,IF(AND(AP8=0,AQ8=0),AR8/1,IF(AND(AP8=0,AR8=0),AQ8/1,IF(AND(AQ8=0,AR8=0),AP8/1,IF(AP8=0,FLOOR((AQ8+AR8)/2,0.1),IF(AQ8=0,(AP8+AR8)/2,IF(AR8=0,(AQ8+AP8)/2,FLOOR(((AP8+AQ8+AR8)/3),0.1)))))))) | AT8: 30 | AU8: 34 | AV8: =SUM(AT8:AU8) | AW8: 40 | AX8: 61 | AY8: =IF(AND(AV8=0,AW8=0,AX8=0),0,IF(AND(AV8=0,AW8=0),AX8/1,IF(AND(AV8=0,AX8=0),AW8/1,IF(AND(AW8=0,AX8=0),AV8/1,IF(AV8=0,FLOOR((AW8+AX8)/2,0.1),IF(AW8=0,(AV8+AX8)/2,IF(AX8=0,(AW8+AV8)/2,FLOOR(((AV8+AW8+AX8)/3),0.1)))))))) | AZ8: 22 | BA8: 32 | BB8: =SUM(AZ8:BA8) | BC8: 64 | BD8: 59 | BE8: =IF(AND(BB8=0,BC8=0,BD8=0),0,IF(AND(BB8=0,BC8=0),BD8/1,IF(AND(BB8=0,BD8=0),BC8/1,IF(AND(BC8=0,BD8=0),BB8/1,IF(BB8=0,FLOOR((BC8+BD8)/2,0.1),IF(BC8=0,(BB8+BD8)/2,IF(BD8=0,(BC8+BB8)/2,FLOOR(((BB8+BC8+BD8)/3),0.1)))))))) | BF8: 13 | BG8: 48 | BH8: =SUM(BF8:BG8) | BI8: 50 | BJ8: 30 | BK8: =IF(AND(BH8=0,BI8=0,BJ8=0),0,IF(AND(BH8=0,BI8=0),BJ8/1,IF(AND(BH8=0,BJ8=0),BI8/1,IF(AND(BI8=0,BJ8=0),BH8/1,IF(BH8=0,FLOOR((BI8+BJ8)/2,0.1),IF(BI8=0,(BH8+BJ8)/2,IF(BJ8=0,(BI8+BH8)/2,FLOOR(((BH8+BI8+BJ8)/3),0.1)))))))) | BL8: 15 | BM8: 37 | BN8: =SUM(BL8:BM8) | BO8: 35 | BP8: 37 | BQ8: =IF(AND(BN8=0,BO8=0,BP8=0),0,IF(AND(BN8=0,BO8=0),BP8/1,IF(AND(BN8=0,BP8=0),BO8/1,IF(AND(BO8=0,BP8=0),BN8/1,IF(BN8=0,FLOOR((BO8+BP8)/2,0.1),IF(BO8=0,(BN8+BP8)/2,IF(BP8=0,(BO8+BN8)/2,FLOOR(((BN8+BO8+BP8)/3),0.1)))))))) | BT8: =SUM(BR8:BS8) | BW8: =IF(AND(BT8=0,BU8=0,BV8=0),0,IF(AND(BT8=0,BU8=0),BV8/1,IF(AND(BT8=0,BV8=0),BU8/1,IF(AND(BU8=0,BV8=0),BT8/1,IF(BT8=0,FLOOR((BU8+BV8)/2,0.1),IF(BU8=0,(BT8+BV8)/2,IF(BV8=0,(BU8+BT8)/2,FLOOR(((BT8+BU8+BV8)/3),0.1)))))))) | BX8: 21 | BY8: 70 | BZ8: =SUM(BX8:BY8) | CA8: 50 | CB8: 39 | CC8: =IF(AND(BZ8=0,CA8=0,CB8=0),0,IF(AND(BZ8=0,CA8=0),CB8/1,IF(AND(BZ8=0,CB8=0),CA8/1,IF(AND(CA8=0,CB8=0),BZ8/1,IF(BZ8=0,FLOOR((CA8+CB8)/2,0.1),IF(CA8=0,(BZ8+CB8)/2,IF(CB8=0,(CA8+BZ8)/2,FLOOR(((BZ8+CA8+CB8)/3),0.1)))))))) | CD8: 15 | CE8: 44 | CF8: =SUM(CD8:CE8) | CG8: 22 | CH8: 38 | CI8: =IF(AND(CF8=0,CG8=0,CH8=0),0,IF(AND(CF8=0,CG8=0),CH8/1,IF(AND(CF8=0,CH8=0),CG8/1,IF(AND(CG8=0,CH8=0),CF8/1,IF(CF8=0,FLOOR((CG8+CH8)/2,0.1),IF(CG8=0,(CF8+CH8)/2,IF(CH8=0,(CG8+CF8)/2,FLOOR(((CF8+CG8+CH8)/3),0.1)))))))) | CL8: =SUM(CJ8:CK8) | CO8: =IF(AND(CL8=0,CM8=0,CN8=0),0,IF(AND(CL8=0,CM8=0),CN8/1,IF(AND(CL8=0,CN8=0),CM8/1,IF(AND(CM8=0,CN8=0),CL8/1,IF(CL8=0,FLOOR((CM8+CN8)/2,0.1),IF(CM8=0,(CL8+CN8)/2,IF(CN8=0,(CM8+CL8)/2,FLOOR(((CL8+CM8+CN8)/3),0.1)))))))) | CR8: =SUM(CP8:CQ8) | CU8: =IF(AND(CR8=0,CS8=0,CT8=0),0,IF(AND(CR8=0,CS8=0),CT8/1,IF(AND(CR8=0,CT8=0),CS8/1,IF(AND(CS8=0,CT8=0),CR8/1,IF(CR8=0,FLOOR((CS8+CT8)/2,0.1),IF(CS8=0,(CR8+CT8)/2,IF(CT8=0,(CS8+CR8)/2,FLOOR(((CR8+CS8+CT8)/3),0.1)))))))) | CV8: 10 | CW8: 22 | CX8: =SUM(CV8:CW8) | CY8: 42 | CZ8: 37 | DA8: =IF(AND(CX8=0,CY8=0,CZ8=0),0,IF(AND(CX8=0,CY8=0),CZ8/1,IF(AND(CX8=0,CZ8=0),CY8/1,IF(AND(CY8=0,CZ8=0),CX8/1,IF(CX8=0,FLOOR((CY8+CZ8)/2,0.1),IF(CY8=0,(CX8+CZ8)/2,IF(CZ8=0,(CY8+CX8)/2,FLOOR(((CX8+CY8+CZ8)/3),0.1)))))))) | DD8: =SUM(DB8:DC8) | DG8: =IF(AND(DD8=0,DE8=0,DF8=0),0,IF(AND(DD8=0,DE8=0),DF8/1,IF(AND(DD8=0,DF8=0),DE8/1,IF(AND(DE8=0,DF8=0),DD8/1,IF(DD8=0,FLOOR((DE8+DF8)/2,0.1),IF(DE8=0,(DD8+DF8)/2,IF(DF8=0,(DE8+DD8)/2,FLOOR(((DD8+DE8+DF8)/3),0.1)))))))) | DH8: =SUM(O8,U8,AA8,AG8,AM8,AS8,AY8,BE8,BK8,BQ8,BW8,CC8,CI8,CO8,CU8,DA8,DG8) | DI8: =RANK(DH8,DH$4:DH$503) | DJ8: GOOD(4) | DK8: GOOD(4) | DL8: GOOD(4) | DM8: EXCELLENT(5) | DN8: GOOD(4) | DO8: GOOD(4) | DP8: GOOD(4) | DQ8: GOOD(4) | DR8: 2024/2025 | DS8: THIRD | DT8: GOOD(4) | DU8: GOOD(4) | DV8: GOOD(4) | DW8: GOOD(4) | DX8: GOOD(4) | DY8: GOOD(4) | DZ8: GOOD(4) | EA8: Requires additional support in understanding key concepts. | EB8: Promoted to JSS3 | EC8: MR. JIMOH WASIU OLATUNDE | ED8: Next Term Begins on Monday, 15th September, 2029
A9: 6 | B9: ALABI OJEDAYO A. | C9: 1847 | D9: Male | E9: JSS 2C | F9: 31 | G9: 122 | H9: 110 | I9: =G9-H9 | J9: 30 | K9: 42 | L9: =SUM(J9:K9) | M9: 22 | N9: 35 | O9: =IF(AND(L9=0,M9=0,N9=0),0,IF(AND(L9=0,M9=0),N9/1,IF(AND(L9=0,N9=0),M9/1,IF(AND(M9=0,N9=0),L9/1,IF(L9=0,FLOOR((M9+N9)/2,0.1),IF(M9=0,(L9+N9)/2,IF(N9=0,(M9+L9)/2,FLOOR(((L9+M9+N9)/3),0.1)))))))) | P9: 16 | Q9: 33 | R9: =SUM(P9:Q9) | S9: 54 | T9: 45 | U9: =IF(AND(R9=0,S9=0,T9=0),0,IF(AND(R9=0,S9=0),T9/1,IF(AND(R9=0,T9=0),S9/1,IF(AND(S9=0,T9=0),R9/1,IF(R9=0,FLOOR((S9+T9)/2,0.1),IF(S9=0,(R9+T9)/2,IF(T9=0,(S9+R9)/2,FLOOR(((R9+S9+T9)/3),0.1)))))))) | V9: 25 | W9: 20 | X9: =SUM(V9:W9) | Y9: 52 | Z9: 48 | AA9: =IF(AND(X9=0,Y9=0,Z9=0),0,IF(AND(X9=0,Y9=0),Z9/1,IF(AND(X9=0,Z9=0),Y9/1,IF(AND(Y9=0,Z9=0),X9/1,IF(X9=0,FLOOR((Y9+Z9)/2,0.1),IF(Y9=0,(X9+Z9)/2,IF(Z9=0,(Y9+X9)/2,FLOOR(((X9+Y9+Z9)/3),0.1)))))))) | AB9: 17 | AC9: 35 | AD9: =SUM(AB9:AC9) | AE9: 58 | AF9: 53 | AG9: =IF(AND(AD9=0,AE9=0,AF9=0),0,IF(AND(AD9=0,AE9=0),AF9/1,IF(AND(AD9=0,AF9=0),AE9/1,IF(AND(AE9=0,AF9=0),AD9/1,IF(AD9=0,FLOOR((AE9+AF9)/2,0.1),IF(AE9=0,(AD9+AF9)/2,IF(AF9=0,(AE9+AD9)/2,FLOOR(((AD9+AE9+AF9)/3),0.1)))))))) | AH9: 17 | AI9: 29 | AJ9: =SUM(AH9:AI9) | AK9: 54 | AL9: 40 | AM9: =IF(AND(AJ9=0,AK9=0,AL9=0),0,IF(AND(AJ9=0,AK9=0),AL9/1,IF(AND(AJ9=0,AL9=0),AK9/1,IF(AND(AK9=0,AL9=0),AJ9/1,IF(AJ9=0,FLOOR((AK9+AL9)/2,0.1),IF(AK9=0,(AJ9+AL9)/2,IF(AL9=0,(AK9+AJ9)/2,FLOOR(((AJ9+AK9+AL9)/3),0.1)))))))) | AP9: =SUM(AN9:AO9) | AS9: =IF(AND(AP9=0,AQ9=0,AR9=0),0,IF(AND(AP9=0,AQ9=0),AR9/1,IF(AND(AP9=0,AR9=0),AQ9/1,IF(AND(AQ9=0,AR9=0),AP9/1,IF(AP9=0,FLOOR((AQ9+AR9)/2,0.1),IF(AQ9=0,(AP9+AR9)/2,IF(AR9=0,(AQ9+AP9)/2,FLOOR(((AP9+AQ9+AR9)/3),0.1)))))))) | AT9: 23 | AU9: 33 | AV9: =SUM(AT9:AU9) | AW9: 38 | AX9: 39 | AY9: =IF(AND(AV9=0,AW9=0,AX9=0),0,IF(AND(AV9=0,AW9=0),AX9/1,IF(AND(AV9=0,AX9=0),AW9/1,IF(AND(AW9=0,AX9=0),AV9/1,IF(AV9=0,FLOOR((AW9+AX9)/2,0.1),IF(AW9=0,(AV9+AX9)/2,IF(AX9=0,(AW9+AV9)/2,FLOOR(((AV9+AW9+AX9)/3),0.1)))))))) | AZ9: 17 | BA9: 33 | BB9: =SUM(AZ9:BA9) | BC9: 45 | BD9: 48 | BE9: =IF(AND(BB9=0,BC9=0,BD9=0),0,IF(AND(BB9=0,BC9=0),BD9/1,IF(AND(BB9=0,BD9=0),BC9/1,IF(AND(BC9=0,BD9=0),BB9/1,IF(BB9=0,FLOOR((BC9+BD9)/2,0.1),IF(BC9=0,(BB9+BD9)/2,IF(BD9=0,(BC9+BB9)/2,FLOOR(((BB9+BC9+BD9)/3),0.1)))))))) | BF9: 16 | BG9: 35 | BH9: =SUM(BF9:BG9) | BI9: 48 | BJ9: 37 | BK9: =IF(AND(BH9=0,BI9=0,BJ9=0),0,IF(AND(BH9=0,BI9=0),BJ9/1,IF(AND(BH9=0,BJ9=0),BI9/1,IF(AND(BI9=0,BJ9=0),BH9/1,IF(BH9=0,FLOOR((BI9+BJ9)/2,0.1),IF(BI9=0,(BH9+BJ9)/2,IF(BJ9=0,(BI9+BH9)/2,FLOOR(((BH9+BI9+BJ9)/3),0.1)))))))) | BL9: 23 | BM9: 35 | BN9: =SUM(BL9:BM9) | BO9: 47 | BP9: 57 | BQ9: =IF(AND(BN9=0,BO9=0,BP9=0),0,IF(AND(BN9=0,BO9=0),BP9/1,IF(AND(BN9=0,BP9=0),BO9/1,IF(AND(BO9=0,BP9=0),BN9/1,IF(BN9=0,FLOOR((BO9+BP9)/2,0.1),IF(BO9=0,(BN9+BP9)/2,IF(BP9=0,(BO9+BN9)/2,FLOOR(((BN9+BO9+BP9)/3),0.1)))))))) | BT9: =SUM(BR9:BS9) | BW9: =IF(AND(BT9=0,BU9=0,BV9=0),0,IF(AND(BT9=0,BU9=0),BV9/1,IF(AND(BT9=0,BV9=0),BU9/1,IF(AND(BU9=0,BV9=0),BT9/1,IF(BT9=0,FLOOR((BU9+BV9)/2,0.1),IF(BU9=0,(BT9+BV9)/2,IF(BV9=0,(BU9+BT9)/2,FLOOR(((BT9+BU9+BV9)/3),0.1)))))))) | BX9: 23 | BY9: 59 | BZ9: =SUM(BX9:BY9) | CA9: 47 | CB9: 42 | CC9: =IF(AND(BZ9=0,CA9=0,CB9=0),0,IF(AND(BZ9=0,CA9=0),CB9/1,IF(AND(BZ9=0,CB9=0),CA9/1,IF(AND(CA9=0,CB9=0),BZ9/1,IF(BZ9=0,FLOOR((CA9+CB9)/2,0.1),IF(CA9=0,(BZ9+CB9)/2,IF(CB9=0,(CA9+BZ9)/2,FLOOR(((BZ9+CA9+CB9)/3),0.1)))))))) | CD9: 15 | CE9: 38 | CF9: =SUM(CD9:CE9) | CG9: 27 | CH9: 29 | CI9: =IF(AND(CF9=0,CG9=0,CH9=0),0,IF(AND(CF9=0,CG9=0),CH9/1,IF(AND(CF9=0,CH9=0),CG9/1,IF(AND(CG9=0,CH9=0),CF9/1,IF(CF9=0,FLOOR((CG9+CH9)/2,0.1),IF(CG9=0,(CF9+CH9)/2,IF(CH9=0,(CG9+CF9)/2,FLOOR(((CF9+CG9+CH9)/3),0.1)))))))) | CL9: =SUM(CJ9:CK9) | CO9: =IF(AND(CL9=0,CM9=0,CN9=0),0,IF(AND(CL9=0,CM9=0),CN9/1,IF(AND(CL9=0,CN9=0),CM9/1,IF(AND(CM9=0,CN9=0),CL9/1,IF(CL9=0,FLOOR((CM9+CN9)/2,0.1),IF(CM9=0,(CL9+CN9)/2,IF(CN9=0,(CM9+CL9)/2,FLOOR(((CL9+CM9+CN9)/3),0.1)))))))) | CR9: =SUM(CP9:CQ9) | CU9: =IF(AND(CR9=0,CS9=0,CT9=0),0,IF(AND(CR9=0,CS9=0),CT9/1,IF(AND(CR9=0,CT9=0),CS9/1,IF(AND(CS9=0,CT9=0),CR9/1,IF(CR9=0,FLOOR((CS9+CT9)/2,0.1),IF(CS9=0,(CR9+CT9)/2,IF(CT9=0,(CS9+CR9)/2,FLOOR(((CR9+CS9+CT9)/3),0.1)))))))) | CV9: 28 | CW9: 25 | CX9: =SUM(CV9:CW9) | CY9: 29 | CZ9: 20 | DA9: =IF(AND(CX9=0,CY9=0,CZ9=0),0,IF(AND(CX9=0,CY9=0),CZ9/1,IF(AND(CX9=0,CZ9=0),CY9/1,IF(AND(CY9=0,CZ9=0),CX9/1,IF(CX9=0,FLOOR((CY9+CZ9)/2,0.1),IF(CY9=0,(CX9+CZ9)/2,IF(CZ9=0,(CY9+CX9)/2,FLOOR(((CX9+CY9+CZ9)/3),0.1)))))))) | DD9: =SUM(DB9:DC9) | DG9: =IF(AND(DD9=0,DE9=0,DF9=0),0,IF(AND(DD9=0,DE9=0),DF9/1,IF(AND(DD9=0,DF9=0),DE9/1,IF(AND(DE9=0,DF9=0),DD9/1,IF(DD9=0,FLOOR((DE9+DF9)/2,0.1),IF(DE9=0,(DD9+DF9)/2,IF(DF9=0,(DE9+DD9)/2,FLOOR(((DD9+DE9+DF9)/3),0.1)))))))) | DH9: =SUM(O9,U9,AA9,AG9,AM9,AS9,AY9,BE9,BK9,BQ9,BW9,CC9,CI9,CO9,CU9,DA9,DG9) | DI9: =RANK(DH9,DH$4:DH$503) | DJ9: GOOD(4) | DK9: GOOD(4) | DL9: GOOD(4) | DM9: EXCELLENT(5) | DN9: GOOD(4) | DO9: GOOD(4) | DP9: GOOD(4) | DQ9: GOOD(4) | DR9: 2024/2025 | DS9: THIRD | DT9: GOOD(4) | DU9: GOOD(4) | DV9: GOOD(4) | DW9: GOOD(4) | DX9: GOOD(4) | DY9: GOOD(4) | DZ9: GOOD(4) | EA9: Excels in most subjects and demonstrates a strong grasp of concepts. | EB9: Promoted to JSS3 | EC9: MR. JIMOH WASIU OLATUNDE | ED9: Next Term Begins on Monday, 15th September, 2030
A10: 7 | B10: ALABI SANGODAMOLA | C10: 1868 | D10: Male | E10: JSS 2C | F10: 31 | G10: 122 | H10: 102 | I10: =G10-H10 | J10: 30 | K10: 34 | L10: =SUM(J10:K10) | M10: 30 | N10: 61 | O10: =IF(AND(L10=0,M10=0,N10=0),0,IF(AND(L10=0,M10=0),N10/1,IF(AND(L10=0,N10=0),M10/1,IF(AND(M10=0,N10=0),L10/1,IF(L10=0,FLOOR((M10+N10)/2,0.1),IF(M10=0,(L10+N10)/2,IF(N10=0,(M10+L10)/2,FLOOR(((L10+M10+N10)/3),0.1)))))))) | P10: 20 | Q10: 40 | R10: =SUM(P10:Q10) | S10: 71 | T10: 50 | U10: =IF(AND(R10=0,S10=0,T10=0),0,IF(AND(R10=0,S10=0),T10/1,IF(AND(R10=0,T10=0),S10/1,IF(AND(S10=0,T10=0),R10/1,IF(R10=0,FLOOR((S10+T10)/2,0.1),IF(S10=0,(R10+T10)/2,IF(T10=0,(S10+R10)/2,FLOOR(((R10+S10+T10)/3),0.1)))))))) | V10: 20 | W10: 30 | X10: =SUM(V10:W10) | Y10: 62 | Z10: 56 | AA10: =IF(AND(X10=0,Y10=0,Z10=0),0,IF(AND(X10=0,Y10=0),Z10/1,IF(AND(X10=0,Z10=0),Y10/1,IF(AND(Y10=0,Z10=0),X10/1,IF(X10=0,FLOOR((Y10+Z10)/2,0.1),IF(Y10=0,(X10+Z10)/2,IF(Z10=0,(Y10+X10)/2,FLOOR(((X10+Y10+Z10)/3),0.1)))))))) | AB10: 25 | AC10: 29 | AD10: =SUM(AB10:AC10) | AE10: 55 | AF10: 54 | AG10: =IF(AND(AD10=0,AE10=0,AF10=0),0,IF(AND(AD10=0,AE10=0),AF10/1,IF(AND(AD10=0,AF10=0),AE10/1,IF(AND(AE10=0,AF10=0),AD10/1,IF(AD10=0,FLOOR((AE10+AF10)/2,0.1),IF(AE10=0,(AD10+AF10)/2,IF(AF10=0,(AE10+AD10)/2,FLOOR(((AD10+AE10+AF10)/3),0.1)))))))) | AH10: 30 | AI10: 33 | AJ10: =SUM(AH10:AI10) | AK10: 28 | AL10: 28 | AM10: =IF(AND(AJ10=0,AK10=0,AL10=0),0,IF(AND(AJ10=0,AK10=0),AL10/1,IF(AND(AJ10=0,AL10=0),AK10/1,IF(AND(AK10=0,AL10=0),AJ10/1,IF(AJ10=0,FLOOR((AK10+AL10)/2,0.1),IF(AK10=0,(AJ10+AL10)/2,IF(AL10=0,(AK10+AJ10)/2,FLOOR(((AJ10+AK10+AL10)/3),0.1)))))))) | AP10: =SUM(AN10:AO10) | AS10: =IF(AND(AP10=0,AQ10=0,AR10=0),0,IF(AND(AP10=0,AQ10=0),AR10/1,IF(AND(AP10=0,AR10=0),AQ10/1,IF(AND(AQ10=0,AR10=0),AP10/1,IF(AP10=0,FLOOR((AQ10+AR10)/2,0.1),IF(AQ10=0,(AP10+AR10)/2,IF(AR10=0,(AQ10+AP10)/2,FLOOR(((AP10+AQ10+AR10)/3),0.1)))))))) | AT10: 27 | AU10: 31 | AV10: =SUM(AT10:AU10) | AW10: 47 | AX10: 38 | AY10: =IF(AND(AV10=0,AW10=0,AX10=0),0,IF(AND(AV10=0,AW10=0),AX10/1,IF(AND(AV10=0,AX10=0),AW10/1,IF(AND(AW10=0,AX10=0),AV10/1,IF(AV10=0,FLOOR((AW10+AX10)/2,0.1),IF(AW10=0,(AV10+AX10)/2,IF(AX10=0,(AW10+AV10)/2,FLOOR(((AV10+AW10+AX10)/3),0.1)))))))) | AZ10: 23 | BA10: 48 | BB10: =SUM(AZ10:BA10) | BC10: 53 | BD10: 62 | BE10: =IF(AND(BB10=0,BC10=0,BD10=0),0,IF(AND(BB10=0,BC10=0),BD10/1,IF(AND(BB10=0,BD10=0),BC10/1,IF(AND(BC10=0,BD10=0),BB10/1,IF(BB10=0,FLOOR((BC10+BD10)/2,0.1),IF(BC10=0,(BB10+BD10)/2,IF(BD10=0,(BC10+BB10)/2,FLOOR(((BB10+BC10+BD10)/3),0.1)))))))) | BF10: 16 | BG10: 35 | BH10: =SUM(BF10:BG10) | BI10: 50 | BJ10: 37 | BK10: =IF(AND(BH10=0,BI10=0,BJ10=0),0,IF(AND(BH10=0,BI10=0),BJ10/1,IF(AND(BH10=0,BJ10=0),BI10/1,IF(AND(BI10=0,BJ10=0),BH10/1,IF(BH10=0,FLOOR((BI10+BJ10)/2,0.1),IF(BI10=0,(BH10+BJ10)/2,IF(BJ10=0,(BI10+BH10)/2,FLOOR(((BH10+BI10+BJ10)/3),0.1)))))))) | BL10: 27 | BM10: 43 | BN10: =SUM(BL10:BM10) | BO10: 32 | BP10: 54 | BQ10: =IF(AND(BN10=0,BO10=0,BP10=0),0,IF(AND(BN10=0,BO10=0),BP10/1,IF(AND(BN10=0,BP10=0),BO10/1,IF(AND(BO10=0,BP10=0),BN10/1,IF(BN10=0,FLOOR((BO10+BP10)/2,0.1),IF(BO10=0,(BN10+BP10)/2,IF(BP10=0,(BO10+BN10)/2,FLOOR(((BN10+BO10+BP10)/3),0.1)))))))) | BT10: =SUM(BR10:BS10) | BW10: =IF(AND(BT10=0,BU10=0,BV10=0),0,IF(AND(BT10=0,BU10=0),BV10/1,IF(AND(BT10=0,BV10=0),BU10/1,IF(AND(BU10=0,BV10=0),BT10/1,IF(BT10=0,FLOOR((BU10+BV10)/2,0.1),IF(BU10=0,(BT10+BV10)/2,IF(BV10=0,(BU10+BT10)/2,FLOOR(((BT10+BU10+BV10)/3),0.1)))))))) | BX10: 20 | BY10: 62 | BZ10: =SUM(BX10:BY10) | CA10: 49 | CB10: 54 | CC10: =IF(AND(BZ10=0,CA10=0,CB10=0),0,IF(AND(BZ10=0,CA10=0),CB10/1,IF(AND(BZ10=0,CB10=0),CA10/1,IF(AND(CA10=0,CB10=0),BZ10/1,IF(BZ10=0,FLOOR((CA10+CB10)/2,0.1),IF(CA10=0,(BZ10+CB10)/2,IF(CB10=0,(CA10+BZ10)/2,FLOOR(((BZ10+CA10+CB10)/3),0.1)))))))) | CD10: 16 | CE10: 38 | CF10: =SUM(CD10:CE10) | CG10: 44 | CH10: 54 | CI10: =IF(AND(CF10=0,CG10=0,CH10=0),0,IF(AND(CF10=0,CG10=0),CH10/1,IF(AND(CF10=0,CH10=0),CG10/1,IF(AND(CG10=0,CH10=0),CF10/1,IF(CF10=0,FLOOR((CG10+CH10)/2,0.1),IF(CG10=0,(CF10+CH10)/2,IF(CH10=0,(CG10+CF10)/2,FLOOR(((CF10+CG10+CH10)/3),0.1)))))))) | CL10: =SUM(CJ10:CK10) | CO10: =IF(AND(CL10=0,CM10=0,CN10=0),0,IF(AND(CL10=0,CM10=0),CN10/1,IF(AND(CL10=0,CN10=0),CM10/1,IF(AND(CM10=0,CN10=0),CL10/1,IF(CL10=0,FLOOR((CM10+CN10)/2,0.1),IF(CM10=0,(CL10+CN10)/2,IF(CN10=0,(CM10+CL10)/2,FLOOR(((CL10+CM10+CN10)/3),0.1)))))))) | CR10: =SUM(CP10:CQ10) | CU10: =IF(AND(CR10=0,CS10=0,CT10=0),0,IF(AND(CR10=0,CS10=0),CT10/1,IF(AND(CR10=0,CT10=0),CS10/1,IF(AND(CS10=0,CT10=0),CR10/1,IF(CR10=0,FLOOR((CS10+CT10)/2,0.1),IF(CS10=0,(CR10+CT10)/2,IF(CT10=0,(CS10+CR10)/2,FLOOR(((CR10+CS10+CT10)/3),0.1)))))))) | CV10: 30 | CW10: 33 | CX10: =SUM(CV10:CW10) | CY10: 28 | CZ10: 28 | DA10: =IF(AND(CX10=0,CY10=0,CZ10=0),0,IF(AND(CX10=0,CY10=0),CZ10/1,IF(AND(CX10=0,CZ10=0),CY10/1,IF(AND(CY10=0,CZ10=0),CX10/1,IF(CX10=0,FLOOR((CY10+CZ10)/2,0.1),IF(CY10=0,(CX10+CZ10)/2,IF(CZ10=0,(CY10+CX10)/2,FLOOR(((CX10+CY10+CZ10)/3),0.1)))))))) | DD10: =SUM(DB10:DC10) | DG10: =IF(AND(DD10=0,DE10=0,DF10=0),0,IF(AND(DD10=0,DE10=0),DF10/1,IF(AND(DD10=0,DF10=0),DE10/1,IF(AND(DE10=0,DF10=0),DD10/1,IF(DD10=0,FLOOR((DE10+DF10)/2,0.1),IF(DE10=0,(DD10+DF10)/2,IF(DF10=0,(DE10+DD10)/2,FLOOR(((DD10+DE10+DF10)/3),0.1)))))))) | DH10: =SUM(O10,U10,AA10,AG10,AM10,AS10,AY10,BE10,BK10,BQ10,BW10,CC10,CI10,CO10,CU10,DA10,DG10) | DI10: =RANK(DH10,DH$4:DH$503) | DJ10: EXCELLENT(5) | DK10: GOOD(4) | DL10: GOOD(4) | DM10: EXCELLENT(5) | DN10: GOOD(4) | DO10: GOOD(4) | DP10: GOOD(4) | DQ10: GOOD(4) | DR10: 2024/2025 | DS10: THIRD | DT10: GOOD(4) | DU10: GOOD(4) | DV10: GOOD(4) | DW10: GOOD(4) | DX10: GOOD(4) | DY10: GOOD(4) | DZ10: GOOD(4) | EA10: Shows consistent effort and improvement in academic work. | EB10: Promoted to JSS3 | EC10: MR. JIMOH WASIU OLATUNDE | ED10: Next Term Begins on Monday, 15th September, 2031
